Workbook
Name aa: [1]Vocab_NameList!$H$2:$H$619
Name ACTIVITY_NAME_COL: [1]Vocab_NameList!$T:$T
Name ACTIVITY_NAME_START: [1]Vocab_NameList!$T$2
Name ACTIVITY_TYPE: [1]Vocab_NameList!$O$2:$O$6
Name ACTIVITY_TYPE_COL: [1]Vocab_NameList!$Q:$Q
Name ACTIVITY_TYPE_START: [1]Vocab_NameList!$Q$2
Name DISTRICT: [1]Vocab_NameList!$B$2:$B$15
Name DISTRICT: [1]Vocab_NameList!$B$2:$B$15
Name DISTRICT: DistCode!$A$2:$A$32
Name DISTRICT_CODE: DistCode!$B$2:$B$32
Name DISTRICTCOL: [1]Vocab_NameList!$F:$F
Name DISTRICTCOL: [1]Vocab_NameList!$F:$F
Name DISTRICTCOL: DistCode!$I:$I
Name DISTRICTSTART: [1]Vocab_NameList!$F$2
Name DISTRICTSTART: [1]Vocab_NameList!$F$2
Name DISTRICTSTART: DistCode!$I$2
Name PO: #REF!
Name PO: #REF!
Name PO_ACRONYM: [1]!Table24[Acronym]
Name Sector: DistCode!$O$2:$O$19
Name SECTORCOL: DistCode!$R:$R
Name SECTORSTART: DistCode!$R$2
Name VCODECOL: [1]Vocab_NameList!$J:$J
Name VCODESTART: [1]Vocab_NameList!$J$2
Name VDC: [1]Vocab_NameList!$G$2:$G$619
Name VDC: [1]Vocab_NameList!$G$2:$G$619
Name VDC: DistCode!$J$2:$J$1410
Name VDC_CODE: [1]Vocab_NameList!$H$2:$H$619
Name VDC_CODE: [2]Vocab_NameList!$H$2:$H$619
Name VDC_CODE: DistCode!$M$2:$M$1410

Sheet Read Me

Sheet Org_Info
A3: ORGANIZATION INFORMATION
A4: Organization Name | C4: *
A5: Acronym | C5: *
A6: Address | C6: *
A7: Organization Type | C7: *
A9: ORGANIZATION HEAD
A10: Name | C10: *
A11: Phone | C11: *
A12: Email | C12: *
A13: Designation | C13: *
A15: REPORTING FOCAL PERSON
A16: Name | C16: *
A17: Phone | C17: *
A18: Email | C18: *
A19: Designation | C19: *
A21: PROJECT DETAILS
A22: Title | C22: *
A23: Approval Status | C23: *
A24: Agreement Date | C24: *
B26: All fields marked with asterisk (*) are compulsory

Sheet 5W
A1: District | B1: Palikas | C1: Palika Ward | D1: VDC | E1: VDC Ward | F1: VDC (ward) to Palika (ward) | G1: Location Detail | H1: Implementing Partner | I1: Funding Organisation | J1: Sector | K1: Activity Type | L1: Name of the Infrastructure | M1: Activity Detail | N1: Curriculum (for Trainings) | O1: Activity Status | P1: Unit (Indicator) | Q1: Physical Target - Planned | R1: Physical Target - Reached | S1: Financial Target(NPR) | T1: Financial Target(NPR) Reached | U1: Reporting Line Ministry | V1: Activity Start Date | W1: Activity End Date | X1: Boys (<18 yr) | Y1: Girls (<18yr) | Z1: Male (>18 yr) | AA1: Female (>18 yr) | AB1: Female Headed HHs | AC1: Elderly (>60 yr) Headed HHs | AD1: Child (0-17) Headed HHs | AE1: Chronically ill / Disabled Individuals | AF1: Contact Name | AG1: Contact Number | AH1: E-mail | AI1: Comments
F2: =IFERROR(VLOOKUP(Table5W[[#This Row],[District]]&Table5W[[#This Row],[VDC]]&Table5W[[#This Row],[VDC Ward]],'Conversion Matrix'!$A$2:$B$5871,2,FALSE),"") | P2: =IFERROR(VLOOKUP(Table5W[[#This Row],[Sector]]&"#"&Table5W[[#This Row],[Activity Type]],DistCode!$T$2:$V$383,3,0),"")
F3: =IFERROR(VLOOKUP(Table5W[[#This Row],[District]]&Table5W[[#This Row],[VDC]]&Table5W[[#This Row],[VDC Ward]],'Conversion Matrix'!$A$2:$B$5871,2,FALSE),"") | P3: =IFERROR(VLOOKUP(Table5W[[#This Row],[Sector]]&"#"&Table5W[[#This Row],[Activity Type]],DistCode!$T$2:$V$383,3,0),"")
F4: =IFERROR(VLOOKUP(Table5W[[#This Row],[District]]&Table5W[[#This Row],[VDC]]&Table5W[[#This Row],[VDC Ward]],'Conversion Matrix'!$A$2:$B$5871,2,FALSE),"") | P4: =IFERROR(VLOOKUP(Table5W[[#This Row],[Sector]]&"#"&Table5W[[#This Row],[Activity Type]],DistCode!$T$2:$V$383,3,0),"")
F5: =IFERROR(VLOOKUP(Table5W[[#This Row],[District]]&Table5W[[#This Row],[VDC]]&Table5W[[#This Row],[VDC Ward]],'Conversion Matrix'!$A$2:$B$5871,2,FALSE),"") | P5: =IFERROR(VLOOKUP(Table5W[[#This Row],[Sector]]&"#"&Table5W[[#This Row],[Activity Type]],DistCode!$T$2:$V$383,3,0),"")
F6: =IFERROR(VLOOKUP(Table5W[[#This Row],[District]]&Table5W[[#This Row],[VDC]]&Table5W[[#This Row],[VDC Ward]],'Conversion Matrix'!$A$2:$B$5871,2,FALSE),"") | P6: =IFERROR(VLOOKUP(Table5W[[#This Row],[Sector]]&"#"&Table5W[[#This Row],[Activity Type]],DistCode!$T$2:$V$383,3,0),"")
F7: =IFERROR(VLOOKUP(Table5W[[#This Row],[District]]&Table5W[[#This Row],[VDC]]&Table5W[[#This Row],[VDC Ward]],'Conversion Matrix'!$A$2:$B$5871,2,FALSE),"") | P7: =IFERROR(VLOOKUP(Table5W[[#This Row],[Sector]]&"#"&Table5W[[#This Row],[Activity Type]],DistCode!$T$2:$V$383,3,0),"")
F8: =IFERROR(VLOOKUP(Table5W[[#This Row],[District]]&Table5W[[#This Row],[VDC]]&Table5W[[#This Row],[VDC Ward]],'Conversion Matrix'!$A$2:$B$5871,2,FALSE),"") | P8: =IFERROR(VLOOKUP(Table5W[[#This Row],[Sector]]&"#"&Table5W[[#This Row],[Activity Type]],DistCode!$T$2:$V$383,3,0),"")
F9: =IFERROR(VLOOKUP(Table5W[[#This Row],[District]]&Table5W[[#This Row],[VDC]]&Table5W[[#This Row],[VDC Ward]],'Conversion Matrix'!$A$2:$B$5871,2,FALSE),"") | P9: =IFERROR(VLOOKUP(Table5W[[#This Row],[Sector]]&"#"&Table5W[[#This Row],[Activity Type]],DistCode!$T$2:$V$383,3,0),"")
F10: =IFERROR(VLOOKUP(Table5W[[#This Row],[District]]&Table5W[[#This Row],[VDC]]&Table5W[[#This Row],[VDC Ward]],'Conversion Matrix'!$A$2:$B$5871,2,FALSE),"") | P10: =IFERROR(VLOOKUP(Table5W[[#This Row],[Sector]]&"#"&Table5W[[#This Row],[Activity Type]],DistCode!$T$2:$V$383,3,0),"")
F11: =IFERROR(VLOOKUP(Table5W[[#This Row],[District]]&Table5W[[#This Row],[VDC]]&Table5W[[#This Row],[VDC Ward]],'Conversion Matrix'!$A$2:$B$5871,2,FALSE),"") | P11: =IFERROR(VLOOKUP(Table5W[[#This Row],[Sector]]&"#"&Table5W[[#This Row],[Activity Type]],DistCode!$T$2:$V$383,3,0),"")
F12: =IFERROR(VLOOKUP(Table5W[[#This Row],[District]]&Table5W[[#This Row],[VDC]]&Table5W[[#This Row],[VDC Ward]],'Conversion Matrix'!$A$2:$B$5871,2,FALSE),"") | P12: =IFERROR(VLOOKUP(Table5W[[#This Row],[Sector]]&"#"&Table5W[[#This Row],[Activity Type]],DistCode!$T$2:$V$383,3,0),"")
F13: =IFERROR(VLOOKUP(Table5W[[#This Row],[District]]&Table5W[[#This Row],[VDC]]&Table5W[[#This Row],[VDC Ward]],'Conversion Matrix'!$A$2:$B$5871,2,FALSE),"") | P13: =IFERROR(VLOOKUP(Table5W[[#This Row],[Sector]]&"#"&Table5W[[#This Row],[Activity Type]],DistCode!$T$2:$V$383,3,0),"")
... F30: =IFERROR(VLOOKUP(Table5W[[#This Row],[District]]&Table5W[[#This Row],[VDC]]&Table5W[[#This Row],[VDC Ward]],'Conversion Matrix'!$A$2:$B$5871,2,FALSE),"") | P30: =IFERROR(VLOOKUP(Table5W[[#This Row],[Sector]]&"#"&Table5W[[#This Row],[Activity Type]],DistCode!$T$2:$V$383,3,0),"")

Sheet Activities_Index
A1: Sector | B1: Activities | C1: Type | D1: Indicators
A2: Agriculture, Livestock Development and Irrigation | B2: Analysis - Stress tolerant varieties and breeds | C2: analysis | D2: units
A3: Agriculture, Livestock Development and Irrigation | B3: Assessment - Water management assessment and capacity enhancement | C3: assessments | D3: sites
A4: Agriculture, Livestock Development and Irrigation | B4: Awareness - Crop and livestock diversification | C4: campaigns | D4: households
A5: Agriculture, Livestock Development and Irrigation | B5: Capacity Building - Extension staff/farmers | C5: capacity building | D5: individuals
A6: Agriculture, Livestock Development and Irrigation | B6: Capacity building - Strengthening of Disaster Relief Management Section | C6: capacity building | D6: individuals
A7: Agriculture, Livestock Development and Irrigation | B7: Construction - Market Facility | C7: infrastructures | D7: facilities
A8: Agriculture, Livestock Development and Irrigation | B8: Construction - Multi-Use Water System | C8: infrastructures | D8: constructions
A9: Agriculture, Livestock Development and Irrigation | B9: Construction - Water harvesting pond/tank construction | C9: infrastructures | D9: constructions
A10: Agriculture, Livestock Development and Irrigation | B10: Monitoring - Early warning systems | C10: mechanisms | D10: sites
A11: Agriculture, Livestock Development and Irrigation | B11: Preparedness - Logistic Prepositioning | C11: logistics | D11: units
A12: Agriculture, Livestock Development and Irrigation | B12: Reconstruction - Agricultural and Livestock Resource Center | C12: infrastructures | D12: resource centers
... A384: Water, Sanitation and Hygiene | B384: Support - Water supply in temporary settlements camps | C384: services | D384: households

Sheet DistCode
A1: District | B1: District_Code | C1: DISTRICT | D1: Gapa_NaPa | F1: Type_GN | G1: NEW_WARD_N | I1: District | J1: VDC | K1: DistVDC | L1: OLD_WARD | M1: VDC_Code | O1: Sector | R1: Sector | S1: Activities | T1: ConcatList | U1: Type | V1: Indicators
A2: Bhaktapur | C2: Arghakhanchi | D2: Bhumikasthan Nagarpalika | F2: ARGHAKHANCHIBhumekasthan Nagarpalika | G2: 1 | I2: Arghakhanchi | J2: Adguri | K2: OkhaldhungaPalapu | L2: 1 | M2: 524 3 08 51 5 001 | O2: Agriculture, Livestock Development and Irrigation | R2: Agriculture, Livestock Development and Irrigation | S2: Analysis - Stress tolerant varieties and breeds | T2: =R2&"#"&S2 -> Agriculture, Livestock Development and Irrigation#Analysis - Stress tolerant varieties and breeds | U2: analysis | V2: units
A3: Dhading | C3: Arghakhanchi | D3: Chhatradev Gaunpalika | F3: ARGHAKHANCHIBhumekasthan Nagarpalika | G3: 2 | I3: Arghakhanchi | J3: Arghatos | K3: OkhaldhungaPalapu | L3: 2 | M3: 524 3 08 51 5 003 | O3: Cultural Heritage | R3: Agriculture, Livestock Development and Irrigation | S3: Assessment - Water management assessment and capacity enhancement | T3: =R3&"#"&S3 -> Agriculture, Livestock Development and Irrigation#Assessment - Water management assessment and capacity enhancement | U3: assessments | V3: sites
A4: Dolakha | C4: Arghakhanchi | D4: Malarani Gaunpalika | F4: ARGHAKHANCHIBhumekasthan Nagarpalika | G4: 3 | I4: Arghakhanchi | J4: Asurkot | K4: OkhaldhungaPalapu | L4: 3 | M4: 524 3 08 51 5 004 | O4: Disaster Risk Management | R4: Agriculture, Livestock Development and Irrigation | S4: Awareness - Crop and livestock diversification | T4: =R4&"#"&S4 -> Agriculture, Livestock Development and Irrigation#Awareness - Crop and livestock diversification | U4: campaigns | V4: households
A5: Gorkha | C5: Arghakhanchi | D5: Panini Gaunpalika | F5: ARGHAKHANCHIBhumekasthan Nagarpalika | G5: 4 | I5: Arghakhanchi | J5: Balkot | K5: OkhaldhungaPalapu | L5: 4 | M5: 524 3 08 51 5 005 | O5: Education | R5: Agriculture, Livestock Development and Irrigation | S5: Capacity Building - Extension staff/farmers | T5: =R5&"#"&S5 -> Agriculture, Livestock Development and Irrigation#Capacity Building - Extension staff/farmers | U5: capacity building | V5: individuals
A6: Kathmandu | C6: Arghakhanchi | D6: Sandhikharka Nagarpalika | F6: ARGHAKHANCHIBhumekasthan Nagarpalika | G6: 5 | I6: Arghakhanchi | J6: Bangi | K6: OkhaldhungaPalapu | L6: 5 | M6: 524 3 08 51 5 006 | O6: Electricity and Renewable Energy | R6: Agriculture, Livestock Development and Irrigation | S6: Capacity building - Strengthening of Disaster Relief Management Section | T6: =R6&"#"&S6 -> Agriculture, Livestock Development and Irrigation#Capacity building - Strengthening of Disaster Relief Management Section | U6: capacity building | V6: individuals
A7: Kavrepalanchok | C7: Arghakhanchi | D7: Sitganga Nagarpalika | F7: ARGHAKHANCHIBhumekasthan Nagarpalika | G7: 6 | I7: Arghakhanchi | J7: Bhagawati | K7: OkhaldhungaPalapu | L7: 6 | M7: 524 3 08 51 5 008 | O7: Employment and Livelihood | R7: Agriculture, Livestock Development and Irrigation | S7: Construction - Market Facility | T7: =R7&"#"&S7 -> Agriculture, Livestock Development and Irrigation#Construction - Market Facility | U7: infrastructures | V7: facilities
A8: Lalitpur | C8: Baglung | D8: Badigad Gaunpalika | F8: ARGHAKHANCHIBhumekasthan Nagarpalika | G8: 7 | I8: Arghakhanchi | J8: Chhatraganj | K8: OkhaldhungaPalapu | L8: 7 | M8: 524 3 08 51 5 009 | O8: Environment and Forestry | R8: Agriculture, Livestock Development and Irrigation | S8: Construction - Multi-Use Water System | T8: =R8&"#"&S8 -> Agriculture, Livestock Development and Irrigation#Construction - Multi-Use Water System | U8: infrastructures | V8: constructions
A9: Makwanpur | C9: Baglung | D9: Baglung Nagarpalika | F9: ARGHAKHANCHIBhumekasthan Nagarpalika | G9: 8 | I9: Arghakhanchi | J9: Chidika | K9: OkhaldhungaPalapu | L9: 8 | M9: 524 3 08 51 5 010 | O9: Gender Equality and Social Inclusion | R9: Agriculture, Livestock Development and Irrigation | S9: Construction - Water harvesting pond/tank construction | T9: =R9&"#"&S9 -> Agriculture, Livestock Development and Irrigation#Construction - Water harvesting pond/tank construction | U9: infrastructures | V9: constructions
A10: Nuwakot | C10: Baglung | D10: Bareng Gaunpalika | F10: ARGHAKHANCHIBhumekasthan Nagarpalika | G10: 9 | I10: Arghakhanchi | J10: Dhakawang | K10: OkhaldhungaPalapu | L10: 9 | M10: 524 3 08 51 5 011 | O10: Governance | R10: Agriculture, Livestock Development and Irrigation | S10: Monitoring - Early warning systems | T10: =R10&"#"&S10 -> Agriculture, Livestock Development and Irrigation#Monitoring - Early warning systems | U10: mechanisms | V10: sites
A11: Okhaldhunga | C11: Baglung | D11: Dhorpatan HR Hunting Reserve | F11: ARGHAKHANCHIBhumekasthan Nagarpalika | G11: 10 | I11: Arghakhanchi | J11: Dhanchaur | K11: OkhaldhungaKalikadevi | L11: 1 | M11: 524 3 08 51 5 012 | O11: Government buildings | R11: Agriculture, Livestock Development and Irrigation | S11: Preparedness - Logistic Prepositioning | T11: =R11&"#"&S11 -> Agriculture, Livestock Development and Irrigation#Preparedness - Logistic Prepositioning | U11: logistics | V11: units
A12: Ramechhap | C12: Baglung | D12: Dhorpatan Nagarpalika | F12: ARGHAKHANCHIChhatradev Gaunpalika | G12: 1 | I12: Arghakhanchi | J12: Dharapani | K12: OkhaldhungaKalikadevi | L12: 2 | M12: 524 3 08 51 5 013 | O12: Health | R12: Agriculture, Livestock Development and Irrigation | S12: Reconstruction - Agricultural and Livestock Resource Center | T12: =R12&"#"&S12 -> Agriculture, Livestock Development and Irrigation#Reconstruction - Agricultural and Livestock Resource Center | U12: infrastructures | V12: resource centers
A13: Rasuwa | C13: Baglung | D13: Galkot Nagarpalika | F13: ARGHAKHANCHIChhatradev Gaunpalika | G13: 2 | I13: Arghakhanchi | J13: Dhatiwang | K13: OkhaldhungaKalikadevi | L13: 3 | M13: 524 3 08 51 5 014 | O13: Nutrition | R13: Agriculture, Livestock Development and Irrigation | S13: Reconstruction - Grain mills including water mill | T13: =R13&"#"&S13 -> Agriculture, Livestock Development and Irrigation#Reconstruction - Grain mills including water mill | U13: infrastructures | V13: mills
... A19: Bhojpur | C19: Bhaktapur | D19: Bhaktapur Nagarpalika | F19: ARGHAKHANCHIChhatradev Gaunpalika | G19: 8 | I19: Arghakhanchi | J19: Kerunga | K19: OkhaldhungaFediguth | L19: 1 | M19: 524 3 08 51 5 022 | O19: Water, Sanitation and Hygiene | R19: Agriculture, Livestock Development and Irrigation | S19: Reconstruction/rehabilitation - Warehouses for agro-products | T19: =R19&"#"&S19 -> Agriculture, Livestock Development and Irrigation#Reconstruction/rehabilitation - Warehouses for agro-products | U19: infrastructures | V19: warehouses
A20: Chitwan | C20: Bhaktapur | D20: Changunarayan Nagarpalika | F20: ARGHAKHANCHIMalarani Gaunpalika | G20: 1 | I20: Arghakhanchi | J20: Khan | K20: OkhaldhungaFediguth | L20: 2 | M20: 524 3 08 51 5 023 | R20: Agriculture, Livestock Development and Irrigation | S20: Support - Enhancement of Crop production | T20: =R20&"#"&S20 -> Agriculture, Livestock Development and Irrigation#Support - Enhancement of Crop production | U20: services | V20: households
A21: Dhankuta | C21: Bhaktapur | D21: Madhyapur Thimi Nagarpalika | F21: ARGHAKHANCHIMalarani Gaunpalika | G21: 2 | I21: Arghakhanchi | J21: Khandaha | K21: OkhaldhungaFediguth | L21: 3 | M21: 524 3 08 51 5 025 | R21: Agriculture, Livestock Development and Irrigation | S21: Support - Enhancement of Livestock production | T21: =R21&"#"&S21 -> Agriculture, Livestock Development and Irrigation#Support - Enhancement of Livestock production | U21: services | V21: households
A22: Gulmi | C22: Bhaktapur | D22: Suryabinayak Nagarpalika | F22: ARGHAKHANCHIMalarani Gaunpalika | G22: 3 | I22: Arghakhanchi | J22: Khidim | K22: OkhaldhungaFediguth | L22: 9 | M22: 524 3 08 51 5 026 | R22: Agriculture, Livestock Development and Irrigation | S22: Support - Extension services, technical support and outreach | T22: =R22&"#"&S22 -> Agriculture, Livestock Development and Irrigation#Support - Extension services, technical support and outreach | U22: services | V22: households
A23: Kaski | C23: Bhojpur | D23: Aamchowk Gaunpalika | F23: ARGHAKHANCHIMalarani Gaunpalika | G23: 4 | I23: Arghakhanchi | J23: Khilji | K23: OkhaldhungaFediguth | L23: 4 | M23: 524 3 08 51 5 027 | R23: Agriculture, Livestock Development and Irrigation | S23: Support - Horticulture facilities | T23: =R23&"#"&S23 -> Agriculture, Livestock Development and Irrigation#Support - Horticulture facilities | U23: services | V23: households
A24: Khotang | C24: Bhojpur | D24: Arun Gaunpalika | F24: ARGHAKHANCHIMalarani Gaunpalika | G24: 5 | I24: Arghakhanchi | J24: Maidan | K24: OkhaldhungaFediguth | L24: 5 | M24: 524 3 08 51 5 028 | R24: Agriculture, Livestock Development and Irrigation | S24: Support - Improved livestock management | T24: =R24&"#"&S24 -> Agriculture, Livestock Development and Irrigation#Support - Improved livestock management | U24: services | V24: households
A25: Lamjung | C25: Bhojpur | D25: Bhojpur Nagarpalika | F25: ARGHAKHANCHIMalarani Gaunpalika | G25: 6 | I25: Arghakhanchi | J25: Mareng | K25: OkhaldhungaFediguth | L25: 6 | M25: 524 3 08 51 5 029 | R25: Agriculture, Livestock Development and Irrigation | S25: Support - Integrated dairy processing | T25: =R25&"#"&S25 -> Agriculture, Livestock Development and Irrigation#Support - Integrated dairy processing | U25: centers | V25: facilities
A26: Myagdi | C26: Bhojpur | D26: Hatuwagadhi Gaunpalika | F26: ARGHAKHANCHIMalarani Gaunpalika | G26: 7 | I26: Arghakhanchi | J26: Nuwakot | K26: OkhaldhungaFediguth | L26: 7 | M26: 524 3 08 51 5 031 | R26: Agriculture, Livestock Development and Irrigation | S26: Support - Market Development/market linkages | T26: =R26&"#"&S26 -> Agriculture, Livestock Development and Irrigation#Support - Market Development/market linkages | U26: services | V26: wards
A27: Nawalparasi | C27: Bhojpur | D27: Pauwadungma Gaunpalika | F27: ARGHAKHANCHIMalarani Gaunpalika | G27: 8 | I27: Arghakhanchi | J27: Pali | K27: OkhaldhungaFediguth | L27: 8 | M27: 524 3 08 51 5 032 | R27: Agriculture, Livestock Development and Irrigation | S27: Support - Meat and Food handling/processing | T27: =R27&"#"&S27 -> Agriculture, Livestock Development and Irrigation#Support - Meat and Food handling/processing | U27: services | V27: centers
A28: Palpa | C28: Bhojpur | D28: Ramprasad Rai Gaunpalika | F28: ARGHAKHANCHIMalarani Gaunpalika | G28: 9 | I28: Arghakhanchi | J28: Pathauti | K28: OkhaldhungaFulbari | L28: 1 | M28: 524 3 08 51 5 033 | R28: Agriculture, Livestock Development and Irrigation | S28: Support - Post-Harvest facilities | T28: =R28&"#"&S28 -> Agriculture, Livestock Development and Irrigation#Support - Post-Harvest facilities | U28: services | V28: households
A29: Parbat | C29: Bhojpur | D29: Salpasilichho Gaunpalika | F29: ARGHAKHANCHIPanini Gaunpalika | G29: 1 | I29: Arghakhanchi | J29: Pathona | K29: OkhaldhungaFulbari | L29: 2 | M29: 524 3 08 51 5 034 | R29: Agriculture, Livestock Development and Irrigation | S29: Support - Replacement of Agricultural inputs, tool and machinery | T29: =R29&"#"&S29 -> Agriculture, Livestock Development and Irrigation#Support - Replacement of Agricultural inputs, tool and machinery | U29: logistics | V29: units
A30: Sankhuwasabha | C30: Bhojpur | D30: Shadananda Nagarpalika | F30: ARGHAKHANCHIPanini Gaunpalika | G30: 2 | I30: Arghakhanchi | J30: Pokharathok | K30: OkhaldhungaFulbari | L30: 3 | M30: 524 3 08 51 5 035 | R30: Agriculture, Livestock Development and Irrigation | S30: Support - Replacement of Livestock inputs, tool and machinery | T30: =R30&"#"&S30 -> Agriculture, Livestock Development and Irrigation#Support - Replacement of Livestock inputs, tool and machinery | U30: logistics | V30: units
A31: Solukhumbu | C31: Bhojpur | D31: Tyamkemaiyung Gaunpalika | F31: ARGHAKHANCHIPanini Gaunpalika | G31: 3 | I31: Arghakhanchi | J31: Sandhikharka N.P. | K31: OkhaldhungaFulbari | L31: 4 | M31: 524 3 08 51 3 036 | R31: Agriculture, Livestock Development and Irrigation | S31: Support - Subsidized credit for affected farmers | T31: =R31&"#"&S31 -> Agriculture, Livestock Development and Irrigation#Support - Subsidized credit for affected farmers | U31: services | V31: households
... A33: Tanahun | C33: Chitwan | D33: Chitwan National Park | F33: ARGHAKHANCHIPanini Gaunpalika | G33: 5 | I33: Arghakhanchi | J33: Simalapani | K33: OkhaldhungaFulbari | L33: 6 | M33: 524 3 08 51 5 038 | R33: Cultural Heritage | S33: Analysis - Damage mapping projects | T33: =R33&"#"&S33 -> Cultural Heritage#Analysis - Damage mapping projects | U33: analysis | V33: households
C34: Chitwan | D34: Ichchhyakamana Gaunpalika | F34: ARGHAKHANCHIPanini Gaunpalika | G34: 6 | I34: Arghakhanchi | J34: Sitapur | K34: OkhaldhungaFulbari | L34: 7 | M34: 524 3 08 51 5 039 | R34: Cultural Heritage | S34: Assessment - Physical assessment/verification of damage | T34: =R34&"#"&S34 -> Cultural Heritage#Assessment - Physical assessment/verification of damage | U34: assessments | V34: heritage sites
C35: Chitwan | D35: Kalika Nagarpalika | F35: ARGHAKHANCHIPanini Gaunpalika | G35: 7 | I35: Arghakhanchi | J35: Subarnakhal | K35: OkhaldhungaFulbari | L35: 8 | M35: 524 3 08 51 5 040 | R35: Cultural Heritage | S35: Awareness - Public awareness programs | T35: =R35&"#"&S35 -> Cultural Heritage#Awareness - Public awareness programs | U35: campaigns | V35: individuals
C36: Chitwan | D36: Khairahani Nagarpalika | F36: ARGHAKHANCHIPanini Gaunpalika | G36: 8 | I36: Arghakhanchi | J36: Thada | K36: OkhaldhungaFulbari | L36: 9 | M36: 524 3 08 51 5 041 | R36: Cultural Heritage | S36: Capacity building - Architects/Engineers | T36: =R36&"#"&S36 -> Cultural Heritage#Capacity building - Architects/Engineers | U36: capacity building | V36: individuals
C37: Chitwan | D37: Madi Nagarpalika | F37: ARGHAKHANCHISandhikharka Nagarpalika | G37: 1 | I37: Arghakhanchi | J37: Thulapokhara | K37: OkhaldhungaKalikadevi | L37: 4 | M37: 524 3 08 51 5 042 | R37: Cultural Heritage | S37: Capacity building - Artisan training | T37: =R37&"#"&S37 -> Cultural Heritage#Capacity building - Artisan training | U37: capacity building | V37: individuals
C38: Chitwan | D38: Rapti Nagarpalika | F38: ARGHAKHANCHISandhikharka Nagarpalika | G38: 2 | I38: Baglung | J38: Adhikarichaur | K38: OkhaldhungaBilandu | L38: 1 | M38: 524 3 09 45 5 001 | R38: Cultural Heritage | S38: Capacity building - Communities practicing ICH recovery | T38: =R38&"#"&S38 -> Cultural Heritage#Capacity building - Communities practicing ICH recovery | U38: capacity building | V38: individuals
C39: Chitwan | D39: Ratnanagar Nagarpalika | F39: ARGHAKHANCHISandhikharka Nagarpalika | G39: 3 | I39: Baglung | J39: Amalachaur | K39: OkhaldhungaBilandu | L39: 2 | M39: 524 3 09 45 5 002 | R39: Cultural Heritage | S39: Capacity Building - Coordination and Information Unit within DoA | T39: =R39&"#"&S39 -> Cultural Heritage#Capacity Building - Coordination and Information Unit within DoA | U39: capacity building | V39: institutions
C40: Dhading | D40: Benighat Rorang Gaunpalika | F40: ARGHAKHANCHISandhikharka Nagarpalika | G40: 4 | I40: Baglung | J40: Amarbhumi | K40: OkhaldhungaBilandu | L40: 3 | M40: 524 3 09 45 5 003 | R40: Cultural Heritage | S40: Capacity building - Other | T40: =R40&"#"&S40 -> Cultural Heritage#Capacity building - Other | U40: capacity building | V40: individuals
C41: Dhading | D41: Dhunibesi Nagarpalika | F41: ARGHAKHANCHISandhikharka Nagarpalika | G41: 5 | I41: Baglung | J41: Argal | K41: OkhaldhungaBilandu | L41: 4 | M41: 524 3 09 45 5 004 | R41: Cultural Heritage | S41: Consultation - Archaeological Consultation | T41: =R41&"#"&S41 -> Cultural Heritage#Consultation - Archaeological Consultation | U41: services | V41: consultations
C42: Dhading | D42: Gajuri Gaunpalika | F42: ARGHAKHANCHISandhikharka Nagarpalika | G42: 6 | I42: Baglung | J42: Arjewa | K42: OkhaldhungaBilandu | L42: 5 | M42: 524 3 09 45 5 005 | R42: Cultural Heritage | S42: Monitoring - Geological Investigation | T42: =R42&"#"&S42 -> Cultural Heritage#Monitoring - Geological Investigation | U42: services | V42: sites
C43: Dhading | D43: Galchi Gaunpalika | F43: ARGHAKHANCHISandhikharka Nagarpalika | G43: 7 | I43: Baglung | J43: Baglung N.P. | K43: OkhaldhungaBilandu | L43: 6 | M43: 524 3 09 45 5 030 | R43: Cultural Heritage | S43: Reconstruction/rehabilitation - Monuments | T43: =R43&"#"&S43 -> Cultural Heritage#Reconstruction/rehabilitation - Monuments | U43: infrastructures | V43: monuments
C44: Dhading | D44: Gangajamuna Gaunpalika | F44: ARGHAKHANCHISandhikharka Nagarpalika | G44: 8 | I44: Baglung | J44: Bangodobhan | K44: OkhaldhungaBilandu | L44: 7 | M44: 524 3 09 45 5 012 | R44: Cultural Heritage | S44: Support - Conservation of Artefacts | T44: =R44&"#"&S44 -> Cultural Heritage#Support - Conservation of Artefacts | U44: services | V44: units
C45: Dhading | D45: Jwalamukhi Gaunpalika | F45: ARGHAKHANCHISandhikharka Nagarpalika | G45: 9 | I45: Baglung | J45: Batakachaur | K45: OkhaldhungaBilandu | L45: 8 | M45: 524 3 09 45 3 031 | R45: Cultural Heritage | S45: Support - Database (Arches and inventory of all monuments) | T45: =R45&"#"&S45 -> Cultural Heritage#Support - Database (Arches and inventory of all monuments) | U45: systems | V45: systems
... C291: Tanahun | D291: Shuklagandaki Nagarpalika | F291: CHITAWANBharatpur Mahanagarpalika | G291: 24 | I291: Dolakha | J291: Marbu | K291: OkhaldhungaThoksel | L291: 7 | M291: 524 2 04 22 5 039 | R291: Tourism | S291: Support - Safe Trekking System | T291: =R291&"#"&S291 -> Tourism#Support - Safe Trekking System | U291: services | V291: systems
...

Sheet Conversion Matrix
A1: DIST_VDC_WARD | B1: GP_NP_NEW_WARD | C1: GaPaNa_Ward_Code
A2: OkhaldhungaPalapu1 | B2: Champadevi G.P. - 1 | C2: 12001-1
A3: OkhaldhungaPalapu2 | B3: Champadevi G.P. - 1 | C3: 12001-1
A4: OkhaldhungaPalapu3 | B4: Champadevi G.P. - 1 | C4: 12001-1
A5: OkhaldhungaPalapu4 | B5: Champadevi G.P. - 1 | C5: 12001-1
A6: OkhaldhungaPalapu5 | B6: Champadevi G.P. - 1 | C6: 12001-1
A7: OkhaldhungaPalapu6 | B7: Champadevi G.P. - 2 | C7: 12001-2
A8: OkhaldhungaPalapu7 | B8: Champadevi G.P. - 2 | C8: 12001-2
A9: OkhaldhungaPalapu8 | B9: Champadevi G.P. - 2 | C9: 12001-2
A10: OkhaldhungaPalapu9 | B10: Champadevi G.P. - 2 | C10: 12001-2
A11: OkhaldhungaKalikadevi1 | B11: Champadevi G.P. - 3 | C11: 12001-3
A12: OkhaldhungaKalikadevi2 | B12: Champadevi G.P. - 3 | C12: 12001-3
... A5871: SindhupalchokBadegau7 | B5871: Indrawati G.P. - 6 | C5871: 23006-6
