Workbook
Name Academic_Qualifications: Vocab_NameList!$U$2:$U$8
Name ACTIVITY_CURRICULUM: Vocab_NameList!$P:$P
Name ACTIVITY_LIST: Vocab_NameList!$N$2:$N$19
Name ACTIVITY_START: Vocab_NameList!$P$2
Name CURRICULUM: Vocab_NameList!$Q$2:$Q$6
Name DISTRICT: Vocab_NameList!$B$2:$B$15
Name DISTRICT_CODE: Vocab_NameList!$C$2:$C$15
Name DISTRICTCOL: Vocab_NameList!$F:$F
Name DISTRICTSTART: Vocab_NameList!$F$2
Name PO: Table2[Partner Organisation]
Name PO_ACRONYM: Table2[Acronym]
Name sex: Vocab_NameList!$S$2:$S$3
Name Slicer_Age_Class: #N/A
Name Slicer_Curriculum: #N/A
Name Slicer_Partner_Organisation: #N/A
Name Slicer_Training_Type: #N/A
Name VDC: Vocab_NameList!$G$2:$G$619
Name VDC_CODE: Vocab_NameList!$H$2:$H$619

Sheet Guidance

Sheet Training_Summary
A1: SLICER | B1: 1. Click on the field name to filter the pivot tables by the selected option
B2: 2. Please click on the sign ( ) to clear the filter
B3: VDC Detail | F3: Organisation-wise Detail | J3: Gender-wise Detail
B4: VDC/Municipality | C4: Training Type | D4: Trained | F4: Partner Organisation | G4: Training Type | H4: Trained | J4: Gender | K4: Trained
B5: Baseri | D5: 1 | F5: ACTED | H5: 1 | J5: Female | K5: 1
C6: Short training-Electrician | D6: 1 | G6: Short training-Electrician | H6: 1 | J6: Grand Total | K6: 1
B7: Grand Total | D7: 1 | F7: Grand Total | H7: 1

Sheet Training_DB
A1: SN | B1: District | C1: VDC/Municipality | D1: Ward | E1: Address (Village Name) | F1: Partner Organisation | G1: Implementing Partner | H1: Donor | I1: Training Type | J1: Curriculum | K1: Start Date | L1: End Date | M1: Citizenship No. | N1: Full Name | O1: Age | P1: Gender | Q1: Caste | R1: Contact Number | S1: Academic Qualification | T1: Experience | U1: Comments | V1: HRRP_VDC_Code | W1: Age_Class
A2: =IF(Table1[[#This Row],[District]]<>"",ROW()-1,"") -> 1 | B2: Dhading | C2: Aginchok | D2: 1 | E2: XYZ | F2: ACTED | G2: ACTED | H2: ACTED | I2: Short training-Mason | J2: DUDBC | K2: 42524 | L2: 42531 | M2: 10324/2032 | N2: Ram Bahadur Khatri | O2: 26 | P2: Male | Q2: Brahman | R2: 9823487323 | S2: Primary (Class 5 or below) | T2: 5 | V2: {=INDEX(VDC_CODE,MATCH(Table1[[#This Row],[District]]&Table1[[#This Row],[VDC/Municipality]],Vocab_NameList!$F$2:$F$619&VDC,0))} -> 524 2 05 30 5 001 | W2: =IF(O2="","N/A",IF(O2<18,"0-17",IF(O2<35,"18-34",IF(O2<60,"35-59",IF(2>60,"60+","N/A"))))) -> 18-34
A3: =IF(Table1[[#This Row],[District]]<>"",ROW()-1,"") -> 2 | B3: Dhading | C3: Baseri | D3: 1 | E3: XYZ | F3: ACTED | G3: ACTED | H3: ACTED | I3: Short training-Electrician | J3: DUDBC | K3: 42554 | L3: 42561 | M3: 10324/2034 | N3: Hari Maya Shrestha | O3: 19 | P3: Female | Q3: Newar | R3: 9823487325 | S3: Lower Secondary (Class 6-8) | T3: 5 | V3: {=INDEX(VDC_CODE,MATCH(Table1[[#This Row],[District]]&Table1[[#This Row],[VDC/Municipality]],Vocab_NameList!$F$2:$F$619&VDC,0))} -> 524 2 05 30 5 003 | W3: =IF(O3="","N/A",IF(O3<18,"0-17",IF(O3<35,"18-34",IF(O3<60,"35-59",IF(2>60,"60+","N/A"))))) -> 18-34
A4: =IF(Table1[[#This Row],[District]]<>"",ROW()-1,"") -> 3 | B4: Dhading | C4: Baseri | D4: 1 | E4: XYZ | F4: ACTED | G4: ACTED | H4: ACTED | I4: Vocational training-Mason | J4: CTEVT | K4: 42554 | L4: 42605 | M4: 10324/2036 | N4: Ram Bahadur Gurung | O4: 60 | P4: Male | Q4: Gurung | R4: 9823487323 | S4: Primary (Class 5 or below) | T4: 5 | V4: {=INDEX(VDC_CODE,MATCH(Table1[[#This Row],[District]]&Table1[[#This Row],[VDC/Municipality]],Vocab_NameList!$F$2:$F$619&VDC,0))} -> 524 2 05 30 5 003 | W4: =IF(O4="","N/A",IF(O4<18,"0-17",IF(O4<35,"18-34",IF(O4<60,"35-59",IF(2>60,"60+","N/A"))))) -> N/A
A5: =IF(Table1[[#This Row],[District]]<>"",ROW()-1,"") | V5: {=INDEX(VDC_CODE,MATCH(Table1[[#This Row],[District]]&Table1[[#This Row],[VDC/Municipality]],Vocab_NameList!$F$2:$F$619&VDC,0))} -> #N/A | W5: =IF(O5="","N/A",IF(O5<18,"0-17",IF(O5<35,"18-34",IF(O5<60,"35-59",IF(2>60,"60+","N/A"))))) -> N/A
A6: =IF(Table1[[#This Row],[District]]<>"",ROW()-1,"") | V6: {=INDEX(VDC_CODE,MATCH(Table1[[#This Row],[District]]&Table1[[#This Row],[VDC/Municipality]],Vocab_NameList!$F$2:$F$619&VDC,0))} -> #N/A | W6: =IF(O6="","N/A",IF(O6<18,"0-17",IF(O6<35,"18-34",IF(O6<60,"35-59",IF(2>60,"60+","N/A"))))) -> N/A
A7: =IF(Table1[[#This Row],[District]]<>"",ROW()-1,"") | V7: {=INDEX(VDC_CODE,MATCH(Table1[[#This Row],[District]]&Table1[[#This Row],[VDC/Municipality]],Vocab_NameList!$F$2:$F$619&VDC,0))} -> #N/A | W7: =IF(O7="","N/A",IF(O7<18,"0-17",IF(O7<35,"18-34",IF(O7<60,"35-59",IF(2>60,"60+","N/A"))))) -> N/A
A8: =IF(Table1[[#This Row],[District]]<>"",ROW()-1,"") | V8: {=INDEX(VDC_CODE,MATCH(Table1[[#This Row],[District]]&Table1[[#This Row],[VDC/Municipality]],Vocab_NameList!$F$2:$F$619&VDC,0))} -> #N/A | W8: =IF(O8="","N/A",IF(O8<18,"0-17",IF(O8<35,"18-34",IF(O8<60,"35-59",IF(2>60,"60+","N/A"))))) -> N/A
A9: =IF(Table1[[#This Row],[District]]<>"",ROW()-1,"") | V9: {=INDEX(VDC_CODE,MATCH(Table1[[#This Row],[District]]&Table1[[#This Row],[VDC/Municipality]],Vocab_NameList!$F$2:$F$619&VDC,0))} -> #N/A | W9: =IF(O9="","N/A",IF(O9<18,"0-17",IF(O9<35,"18-34",IF(O9<60,"35-59",IF(2>60,"60+","N/A"))))) -> N/A
A10: =IF(Table1[[#This Row],[District]]<>"",ROW()-1,"") | V10: {=INDEX(VDC_CODE,MATCH(Table1[[#This Row],[District]]&Table1[[#This Row],[VDC/Municipality]],Vocab_NameList!$F$2:$F$619&VDC,0))} -> #N/A | W10: =IF(O10="","N/A",IF(O10<18,"0-17",IF(O10<35,"18-34",IF(O10<60,"35-59",IF(2>60,"60+","N/A"))))) -> N/A
A11: =IF(Table1[[#This Row],[District]]<>"",ROW()-1,"") | V11: {=INDEX(VDC_CODE,MATCH(Table1[[#This Row],[District]]&Table1[[#This Row],[VDC/Municipality]],Vocab_NameList!$F$2:$F$619&VDC,0))} -> #N/A | W11: =IF(O11="","N/A",IF(O11<18,"0-17",IF(O11<35,"18-34",IF(O11<60,"35-59",IF(2>60,"60+","N/A"))))) -> N/A
A12: =IF(Table1[[#This Row],[District]]<>"",ROW()-1,"") | V12: {=INDEX(VDC_CODE,MATCH(Table1[[#This Row],[District]]&Table1[[#This Row],[VDC/Municipality]],Vocab_NameList!$F$2:$F$619&VDC,0))} -> #N/A | W12: =IF(O12="","N/A",IF(O12<18,"0-17",IF(O12<35,"18-34",IF(O12<60,"35-59",IF(2>60,"60+","N/A"))))) -> N/A
A13: =IF(Table1[[#This Row],[District]]<>"",ROW()-1,"") | V13: {=INDEX(VDC_CODE,MATCH(Table1[[#This Row],[District]]&Table1[[#This Row],[VDC/Municipality]],Vocab_NameList!$F$2:$F$619&VDC,0))} -> #N/A | W13: =IF(O13="","N/A",IF(O13<18,"0-17",IF(O13<35,"18-34",IF(O13<60,"35-59",IF(2>60,"60+","N/A"))))) -> N/A
A14: =IF(Table1[[#This Row],[District]]<>"",ROW()-1,"") | V14: {=INDEX(VDC_CODE,MATCH(Table1[[#This Row],[District]]&Table1[[#This Row],[VDC/Municipality]],Vocab_NameList!$F$2:$F$619&VDC,0))} -> #N/A | W14: =IF(O14="","N/A",IF(O14<18,"0-17",IF(O14<35,"18-34",IF(O14<60,"35-59",IF(2>60,"60+","N/A"))))) -> N/A
A15: =IF(Table1[[#This Row],[District]]<>"",ROW()-1,"") | V15: {=INDEX(VDC_CODE,MATCH(Table1[[#This Row],[District]]&Table1[[#This Row],[VDC/Municipality]],Vocab_NameList!$F$2:$F$619&VDC,0))} -> #N/A | W15: =IF(O15="","N/A",IF(O15<18,"0-17",IF(O15<35,"18-34",IF(O15<60,"35-59",IF(2>60,"60+","N/A"))))) -> N/A
A16: =IF(Table1[[#This Row],[District]]<>"",ROW()-1,"") | V16: {=INDEX(VDC_CODE,MATCH(Table1[[#This Row],[District]]&Table1[[#This Row],[VDC/Municipality]],Vocab_NameList!$F$2:$F$619&VDC,0))} -> #N/A | W16: =IF(O16="","N/A",IF(O16<18,"0-17",IF(O16<35,"18-34",IF(O16<60,"35-59",IF(2>60,"60+","N/A"))))) -> N/A
... A40: =IF(Table1[[#This Row],[District]]<>"",ROW()-1,"") | V40: {=INDEX(VDC_CODE,MATCH(Table1[[#This Row],[District]]&Table1[[#This Row],[VDC/Municipality]],Vocab_NameList!$F$2:$F$619&VDC,0))} -> #N/A | W40: =IF(O40="","N/A",IF(O40<18,"0-17",IF(O40<35,"18-34",IF(O40<60,"35-59",IF(2>60,"60+","N/A"))))) -> N/A

Sheet PO_List
A1: Acronym | B1: Partner Organisation
A2: AA | B2: ActionAid
A3: AAA | B3: Aussie Action Abroad
A4: AAR-J | B4: AAR Japan
A5: AC | B5: Architectural Consultant
A6: ACF | B6: Action Contre La Faim
A7: ACN | B7: Asal Chhimekee Nepal
A8: ACT Alliance | B8: ACT Alliance
A9: ACTED | B9: Agency for Technical Cooperation and Development
A10: AD | B10: Architecture & Development
A11: ADH | B11: ADH, Germany Grant
A12: ADRA | B12: ADRA Nepal
... A332: ZOA | B332: ZOA

Sheet Vocab_NameList
A1: Zone | B1: District | C1: District_Code | F1: District | G1: VDC | H1: VDC_Code | J1: PO | K1: ACRONYM | N1: Activity List | P1: Activity_Curriculum | Q1: Curriculum | S1: Sex | U1: Academic_Qualifications
A2: Bagmati | B2: Bhaktapur | C2: 524 2 05 26 | F2: Bhaktapur | G2: Nagarkot N.P. | H2: 524 2 05 26 3 001 | J2: AAR Japan | K2: AAR-J | N2: Short training-Mason | P2: Short training-Mason | Q2: DUDBC | S2: Male | U2: Illiterate
A3: Bagmati | B3: Dhading | C3: 524 2 05 30 | F3: Bhaktapur | G3: Anantalingeshwor N.P. | H3: 524 2 05 26 3 002 | J3: Accountability Lab | K3: AL | N3: Short training-Electrician | P3: Short training-Mason | Q3: CTEVT | S3: Female | U3: Primary (Class 5 or below)
A4: Bagmati | B4: Kathmandu | C4: 524 2 05 27 | F4: Bhaktapur | G4: Bhaktapur N.P. | H4: 524 2 05 26 3 003 | J4: ActionAid | K4: AA | N4: Short training-Carpenter | P4: Short training-Mason | Q4: NSET | U4: Lower Secondary (Class 6-8)
A5: Bagmati | B5: Kavrepalanchok | C5: 524 2 05 24 | F5: Bhaktapur | G5: Changunarayan N.P. | H5: 524 2 05 26 3 004 | J5: Action Contre La Faim | K5: ACF | N5: Short training-Plumber | P5: Short training-Mason | Q5: Self (Prepared and endorsed from DUDBC) | U5: Secondary (Class 9-10)
A6: Bagmati | B6: Lalitpur | C6: 524 2 05 25 | F6: Bhaktapur | G6: Suryabinayak N.P. | H6: 524 2 05 26 3 006 | J6: ADH, Germany Grant | K6: ADH | N6: Short training-Bar bender | P6: Short training-Mason | Q6: Other (Please specify in comments) | U6: Higher Secondary (Class 11-12)
A7: Bagmati | B7: Nuwakot | C7: 524 2 05 28 | F7: Bhaktapur | G7: MadhyapurThimi N.P. | H7: 524 2 05 26 3 012 | J7: ADRA Nepal | K7: ADRA | N7: Short training-Engineers, Sub-engineers | P7: Short training-Engineers, Sub-engineers | Q7: DUDBC | U7: Bachelors
A8: Bagmati | B8: Rasuwa | C8: 524 2 05 29 | F8: Dhading | G8: Aginchok | H8: 524 2 05 30 5 001 | J8: Agency for Technical Cooperation and Development | K8: ACTED | N8: Short training-Social Mobilizer/ BBS messaging | P8: Short training-Engineers, Sub-engineers | Q8: CTEVT | U8: Masters
A9: Bagmati | B9: Sindhupalchok | C9: 524 2 05 23 | F9: Dhading | G9: Baireni | H9: 524 2 05 30 5 002 | J9: AKF | K9: AKF | N9: Short training-Retrofitting training for engineers, sub-engineers | P9: Short training-Engineers, Sub-engineers | Q9: NSET
A10: Gandaki | B10: Gorkha | C10: 524 3 07 36 | F10: Dhading | G10: Baseri | H10: 524 2 05 30 5 003 | J10: All Hands | K10: AH | N10: Short training-Retrofitting training for skilled construction workers | P10: Short training-Engineers, Sub-engineers | Q10: Self (Prepared and endorsed from DUDBC)
A11: Janakpur | B11: Dolakha | C11: 524 2 04 22 | F11: Dhading | G11: Benighat | H11: 524 2 05 30 5 004 | J11: All Hands Volunteers | K11: AHV | N11: Vocational training-Mason | P11: Short training-Engineers, Sub-engineers | Q11: Other (Please specify in comments)
A12: Janakpur | B12: Ramechhap | C12: 524 2 04 21 | F12: Dhading | G12: Bhumesthan | H12: 524 2 05 30 5 005 | J12: American Red Cross | K12: ARC | N12: Vocational training-Carpenter | P12: Short training-Electrician | Q12: DUDBC
A13: Janakpur | B13: Sindhuli | C13: 524 2 04 20 | F13: Dhading | G13: Budhathum | H13: 524 2 05 30 5 006 | J13: Animal Nepal | K13: AN | N13: Vocational training-Electrician | P13: Short training-Electrician | Q13: CTEVT
A14: Narayani | B14: Makwanpur | C14: 524 2 06 31 | F14: Dhading | G14: Chainpur | H14: 524 2 05 30 5 007 | J14: ANSAB/Relief Intl | K14: ANSAB/RI | N14: Vocational training-Plumber | P14: Short training-Electrician | Q14: NSET
A15: Sagarmatha | B15: Okhaldhunga | C15: 524 1 03 12 | F15: Dhading | G15: ChhatreDyaurali | H15: 524 2 05 30 5 008 | J15: Arbeiter-Samariter-Bund Nepal | K15: ASB | N15: Vocational training-Bar bender | P15: Short training-Electrician | Q15: Self (Prepared and endorsed from DUDBC)
F16: Dhading | G16: Darkha | H16: 524 2 05 30 5 009 | J16: Architects Urgent | K16: AU | N16: ToT-ToT for skilled construction workers | P16: Short training-Electrician | Q16: Other (Please specify in comments)
F17: Dhading | G17: Dhola | H17: 524 2 05 30 5 010 | J17: Architectural Consultant | K17: AC | N17: ToT-ToT for Social Mobilizer/BBS messaging | P17: Short training-Carpenter | Q17: DUDBC
F18: Dhading | G18: Dhussa | H18: 524 2 05 30 5 011 | J18: Architecture & Development | K18: AD | N18: ToT-ToT for Engineers, Sub-engineers | P18: Short training-Carpenter | Q18: CTEVT
F19: Dhading | G19: Dhuwakot | H19: 524 2 05 30 5 012 | J19: Architecture Sans Frontieres Nepal (ASF Nepal) | K19: ASF | N19: Other (Please specify in comment) | P19: Short training-Carpenter | Q19: NSET
F20: Dhading | G20: Gajuri | H20: 524 2 05 30 5 013 | J20: ARSOW Nepal | K20: ARSOW | P20: Short training-Carpenter | Q20: Self (Prepared and endorsed from DUDBC)
F21: Dhading | G21: Goganpani | H21: 524 2 05 30 5 014 | J21: Asia Pacific Alliance for Disaster Management | K21: APAD | P21: Short training-Carpenter | Q21: Other (Please specify in comments)
F22: Dhading | G22: Gumdi | H22: 524 2 05 30 5 015 | J22: Association for Solidarity in ASIA | K22: AS-ASIA | P22: Short training-Plumber | Q22: DUDBC
F23: Dhading | G23: Jeewanpur | H23: 524 2 05 30 5 016 | J23: Aussie Action Abroad | K23: AAA | P23: Short training-Plumber | Q23: CTEVT
F24: Dhading | G24: Jharlang | H24: 524 2 05 30 5 017 | J24: Austrian Red Cross | K24: AustRC | P24: Short training-Plumber | Q24: NSET
F25: Dhading | G25: Jogimara | H25: 524 2 05 30 5 018 | J25: Australian Red Cross | K25: AussRC | P25: Short training-Plumber | Q25: Self (Prepared and endorsed from DUDBC)
F26: Dhading | G26: Jyamrung | H26: 524 2 05 30 5 019 | J26: AWO International | K26: AWOI | P26: Short training-Plumber | Q26: Other (Please specify in comments)
F27: Dhading | G27: Kalleri | H27: 524 2 05 30 5 020 | J27: Aythos | K27: AYTHOS | P27: Short training-Bar bender | Q27: DUDBC
F28: Dhading | G28: Katunje | H28: 524 2 05 30 5 021 | J28: Batas Foundation | K28: BATAS | P28: Short training-Bar bender | Q28: CTEVT
F29: Dhading | G29: Kewalpur | H29: 524 2 05 30 5 022 | J29: Belgian RC-Flanders | K29: BRC-FLANDERS | P29: Short training-Bar bender | Q29: NSET
F30: Dhading | G30: Khalte | H30: 524 2 05 30 5 023 | J30: BRAC | K30: BRAC | P30: Short training-Bar bender | Q30: Self (Prepared and endorsed from DUDBC)
F31: Dhading | G31: Khari | H31: 524 2 05 30 5 024 | J31: Buddha Kumari Foundation | K31: BKF | P31: Short training-Bar bender | Q31: Other (Please specify in comments)
... F86: Dolakha | G86: LakuriDada | H86: 524 2 04 22 5 032 | J86: ECON | K86: ECON | P86: ToT-ToT for Engineers, Sub-engineers | Q86: Other (Please specify in comments)
F87: Dolakha | G87: Lamabagar | H87: 524 2 04 22 5 033 | J87: ECO-Nepal | K87: ECO-N
F88: Dolakha | G88: Lamidada | H88: 524 2 04 22 5 034 | J88: Educate the Children | K88: EC
F89: Dolakha | G89: Lapilang | H89: 524 2 04 22 5 035 | J89: EDUCATION for ALL (NEfA) Switzerland | K89: NEfA
F90: Dolakha | G90: Magapauwa | H90: 524 2 04 22 5 036 | J90: Embassy of India Kathmandu | K90: EoI
F91: Dolakha | G91: Malu | H91: 524 2 04 22 5 038 | J91: Emergency Architects | K91: EA
F92: Dolakha | G92: Marbu | H92: 524 2 04 22 5 039 | J92: Engineering Ministries Internationl | K92: EMI
F93: Dolakha | G93: Melung | H93: 524 2 04 22 5 040 | J93: Engineers without Borders Germany | K93: EwB-GER
F94: Dolakha | G94: Mirge | H94: 524 2 04 22 5 041 | J94: Engineers without Borders USA | K94: EwB-USA
...
