Workbook

Sheet General Information
B2: General Information
B4: 1. General Information
B5: Date | C5: =TODAY() -> 43187
B6: Organization | C6: HRRP
B7: Contact Information | C7: Nina Riehle
C8: nina.riehle@gmail.com
C9: +971 52 130 2804
B10: Studied Products | C10: Common building materials used for the reconstruction of housing in Nepal.
B11: Purpose | C11: The GHG reporting shall be used to compare building materials and subsequently advise NGOs and suppliers on environmentally friendly building materials.
B12: Unit of the Analysis | C12: kgCO2 equivalent (kgCO2 e)
B13: Reference Flow | C13: kg
B14: Type of Inventory | C14: Cradle-to-Gate
B15: Limitations | C15: The boundary of this study is cradle-to-gate and thus does not take into account the building use and end-of-life GHG emissions. A separate study would be required to assess and compare the building materials carbon footprint for the whole life-cycle (cradle-to-grave scope).
B17: 2. Boundary Setting
B18: Description | C18: Most of the housing reconstruction activities in Nepal are done by manual labour and thus the construction stage does not result in significant GHG emissions. Moreover, the houses in remote and rural areas are generally not connected to the grid and subsequently the GHG emissions associated with the building use are negligible. Contrary to western countries, most of the GHG emissions for building materials in Nepal are generated during the extraction, production/manufacturing and transportation processes. Hence, this study aims to compare the carbon footprint of different building materials from cradle-to-gate. Cradle-to-gate includes the GHG emissions generated during the material aquisition & pre-processing, production and transportation to the supplier site. The GHG emissions generated by the transport from the supplier site to the construction site are not reflected within the cradle-to-gate scope. The result of this study will be used to inform NGOs and suppliers on environmental friendly building products and shift the market towards those products.

Sheet Building GHG Emissions
B2: Building Greenhouse Gas Emissions
B4: 1. Key
C5: Input Required
C6: No Input Required
B8: 2a) Selection of Building Type as per Nepal Building Typology Vol 1 & 2 | I8: 2b) Provision of Individual Building Dimensions (Alternative to 2a)
B9: Choose Numbers of Floors | D9: 1 Floor | I9: Number of Floors
B10: Choose the Building Type | D10: Brick Masonry Cement Mortar 1F | I10: Building Type
B11: Total GFA (m2) | D11: =IF($D$10="Stone Masonry Cement Mortar 1F",'Stone Masonry Cement Mortar 1F'!C8,0)+IF($D$10="Stone Masonry Mud Mortar 1F",'Stone Masonry Mud Mortar 1F'!C8,0)+IF($D$10="Brick Masonry Cement Mortar 1F",'Brick Masonry Cement Mortar 1F'!C8,0)+IF($D$10="Brick Masonry Mud Mortar 1F",'Brick Masonry Mud Mortar 1F'!C8,0)+IF($D$10="CSEB 1F",'CSEB 1F'!C8,0)+IF($D$10="Earth Bag 1F",'Earth Bag 1F'!C8,0)+IF($D$10="Stone Masonry Cement Mortar 2F",'Stone Masonry Cement Mortar 2F'!C8,0)+IF($D$10="Brick Masonry Cement Mortar 2F",'Brick Masonry Cement Mortar 2F'!C8,0)+IF($D$10="Hollow Concrete Block 2F",'Hollow Concrete Block 2F'!C8,0)+IF($D$10="CSEB 2F",'CSEB 2F'!C8,0)+IF($D$10="Timber Structure 2F",'Timber Structure 2F'!C8,0)+IF($D$10="Bamboo Stone Hybrid 2F",'Bamboo Stone Hybrid 2F'!C8,0) -> 41.275 | I11: Total GFA (m2) | K11: 26
B13: 3a&b) Choose Brick Type (if applicable)
B14: Choose the Brick Type* | D14: Country Fired Brick
B15: *Applicable for brick buildings and timber structure
B17: 4a) Extraction & Production Emissions | I17: 4b) Extraction & Production Emissions
B18: Material | C18: Weight (kg) | D18: kgCO2e/kg material | E18: Total kgCO2e | F18: Total kgCO2e/m2 | I18: Material | J18: Weight (kg) | K18: kgCO2e/kg material | L18: Total kgCO2e | M18: Total kgCO2e/m2
B19: Cement | C19: =IF($D$10="Stone Masonry Cement Mortar 1F",'Stone Masonry Cement Mortar 1F'!C11,0)+IF($D$10="Stone Masonry Mud Mortar 1F",'Stone Masonry Mud Mortar 1F'!C11,0)+IF($D$10="Brick Masonry Cement Mortar 1F",'Brick Masonry Cement Mortar 1F'!C11,0)+IF($D$10="Brick Masonry Mud Mortar 1F",'Brick Masonry Mud Mortar 1F'!C11,0)+IF($D$10="CSEB 1F",'CSEB 1F'!C11,0)+IF($D$10="Earth Bag 1F",'Earth Bag 1F'!C11,0)+IF($D$10="Stone Masonry Cement Mortar 2F",'Stone Masonry Cement Mortar 2F'!C11,0)+IF($D$10="Brick Masonry Cement Mortar 2F",'Brick Masonry Cement Mortar 2F'!C11,0)+IF($D$10="Hollow Concrete Block 2F",'Hollow Concrete Block 2F'!C11,0)+IF($D$10="CSEB 2F",'CSEB 2F'!C11,0)+IF($D$10="Timber Structure 2F",'Timber Structure 2F'!C11,0)+IF($D$10="Bamboo Stone Hybrid 2F",'Bamboo Stone Hybrid 2F'!C11,0) -> 6350 | D19: ='Material GHG'!C10 -> 0.91 | E19: =C19*D19 -> 5778.5 | F19: =E19/$D$11 -> 140 | I19: Cement | K19: ='Material GHG'!C10 -> 0.91 | L19: =J19*K19 -> 0 | M19: =L19/$K$11 -> 0
B20: Aggregates | C20: =IF($D$10="Stone Masonry Cement Mortar 1F",'Stone Masonry Cement Mortar 1F'!C12,0)+IF($D$10="Stone Masonry Mud Mortar 1F",'Stone Masonry Mud Mortar 1F'!C12,0)+IF($D$10="Brick Masonry Cement Mortar 1F",'Brick Masonry Cement Mortar 1F'!C12,0)+IF($D$10="Brick Masonry Mud Mortar 1F",'Brick Masonry Mud Mortar 1F'!C12,0)+IF($D$10="CSEB 1F",'CSEB 1F'!C12,0)+IF($D$10="Earth Bag 1F",'Earth Bag 1F'!C12,0)+IF($D$10="Stone Masonry Cement Mortar 2F",'Stone Masonry Cement Mortar 2F'!C12,0)+IF($D$10="Brick Masonry Cement Mortar 2F",'Brick Masonry Cement Mortar 2F'!C12,0)+IF($D$10="Hollow Concrete Block 2F",'Hollow Concrete Block 2F'!C12,0)+IF($D$10="CSEB 2F",'CSEB 2F'!C12,0)+IF($D$10="Timber Structure 2F",'Timber Structure 2F'!C12,0)+IF($D$10="Bamboo Stone Hybrid 2F",'Bamboo Stone Hybrid 2F'!C12,0) -> 24000 | D20: ='Material GHG'!C11 -> 0.009 | E20: =C20*D20 -> 216 | F20: =E20/$D$11 -> 5.233192 | I20: Aggregates | K20: ='Material GHG'!C11 -> 0.009 | L20: =J20*K20 -> 0 | M20: =L20/$K$11 -> 0
B21: Sand | C21: =IF($D$10="Stone Masonry Cement Mortar 1F",'Stone Masonry Cement Mortar 1F'!C13,0)+IF($D$10="Stone Masonry Mud Mortar 1F",'Stone Masonry Mud Mortar 1F'!C13,0)+IF($D$10="Brick Masonry Cement Mortar 1F",'Brick Masonry Cement Mortar 1F'!C13,0)+IF($D$10="Brick Masonry Mud Mortar 1F",'Brick Masonry Mud Mortar 1F'!C13,0)+IF($D$10="CSEB 1F",'CSEB 1F'!C13,0)+IF($D$10="Earth Bag 1F",'Earth Bag 1F'!C13,0)+IF($D$10="Stone Masonry Cement Mortar 2F",'Stone Masonry Cement Mortar 2F'!C13,0)+IF($D$10="Brick Masonry Cement Mortar 2F",'Brick Masonry Cement Mortar 2F'!C13,0)+IF($D$10="Hollow Concrete Block 2F",'Hollow Concrete Block 2F'!C13,0)+IF($D$10="CSEB 2F",'CSEB 2F'!C13,0)+IF($D$10="Timber Structure 2F",'Timber Structure 2F'!C13,0)+IF($D$10="Bamboo Stone Hybrid 2F",'Bamboo Stone Hybrid 2F'!C13,0) -> 14400 | D21: ='Material GHG'!C12 -> 0.009 | E21: =C21*D21 -> 129.6 | F21: =E21/$D$11 -> 3.1399152 | I21: Sand | K21: ='Material GHG'!C12 -> 0.009 | L21: =J21*K21 -> 0 | M21: =L21/$K$11 -> 0
B22: Steel | C22: =IF($D$10="Stone Masonry Cement Mortar 1F",'Stone Masonry Cement Mortar 1F'!C14,0)+IF($D$10="Stone Masonry Mud Mortar 1F",'Stone Masonry Mud Mortar 1F'!C14,0)+IF($D$10="Brick Masonry Cement Mortar 1F",'Brick Masonry Cement Mortar 1F'!C14,0)+IF($D$10="Brick Masonry Mud Mortar 1F",'Brick Masonry Mud Mortar 1F'!C14,0)+IF($D$10="CSEB 1F",'CSEB 1F'!C14,0)+IF($D$10="Earth Bag 1F",'Earth Bag 1F'!C14,0)+IF($D$10="Stone Masonry Cement Mortar 2F",'Stone Masonry Cement Mortar 2F'!C14,0)+IF($D$10="Brick Masonry Cement Mortar 2F",'Brick Masonry Cement Mortar 2F'!C14,0)+IF($D$10="Hollow Concrete Block 2F",'Hollow Concrete Block 2F'!C14,0)+IF($D$10="CSEB 2F",'CSEB 2F'!C14,0)+IF($D$10="Timber Structure 2F",'Timber Structure 2F'!C14,0)+IF($D$10="Bamboo Stone Hybrid 2F",'Bamboo Stone Hybrid 2F'!C14,0) -> 460 | D22: ='Material GHG'!C13 -> 2.9 | E22: =C22*D22 -> 1334 | F22: =E22/$D$11 -> 32.319806 | I22: Steel | K22: ='Material GHG'!C13 -> 2.9 | L22: =J22*K22 -> 0 | M22: =L22/$K$11 -> 0
B23: Brick | C23: =IF($D$10="Stone Masonry Cement Mortar 1F",'Stone Masonry Cement Mortar 1F'!C15,0)+IF($D$10="Stone Masonry Mud Mortar 1F",'Stone Masonry Mud Mortar 1F'!C15,0)+IF($D$10="Brick Masonry Cement Mortar 1F",'Brick Masonry Cement Mortar 1F'!C15,0)+IF($D$10="Brick Masonry Mud Mortar 1F",'Brick Masonry Mud Mortar 1F'!C15,0)+IF($D$10="CSEB 1F",'CSEB 1F'!C15,0)+IF($D$10="Earth Bag 1F",'Earth Bag 1F'!C15,0)+IF($D$10="Stone Masonry Cement Mortar 2F",'Stone Masonry Cement Mortar 2F'!C15,0)+IF($D$10="Brick Masonry Cement Mortar 2F",'Brick Masonry Cement Mortar 2F'!C15,0)+IF($D$10="Hollow Concrete Block 2F",'Hollow Concrete Block 2F'!C15,0)+IF($D$10="CSEB 2F",'CSEB 2F'!C15,0)+IF($D$10="Timber Structure 2F",'Timber Structure 2F'!C15,0)+IF($D$10="Bamboo Stone Hybrid 2F",'Bamboo Stone Hybrid 2F'!C15,0) -> 66751.002 | D23: ='Material GHG'!C14 -> 0.33482812 | E23: =C23*D23 -> 22350.113 | F23: =E23/$D$11 -> 541.49274 | I23: Brick | K23: ='Material GHG'!C14 -> 0.33482812 | L23: =J23*K23 -> 0 | M23: =L23/$K$11 -> 0
B24: CSEB | C24: =IF($D$10="Stone Masonry Cement Mortar 1F",'Stone Masonry Cement Mortar 1F'!C16,0)+IF($D$10="Stone Masonry Mud Mortar 1F",'Stone Masonry Mud Mortar 1F'!C16,0)+IF($D$10="Brick Masonry Cement Mortar 1F",'Brick Masonry Cement Mortar 1F'!C16,0)+IF($D$10="Brick Masonry Mud Mortar 1F",'Brick Masonry Mud Mortar 1F'!C16,0)+IF($D$10="CSEB 1F",'CSEB 1F'!C16,0)+IF($D$10="Earth Bag 1F",'Earth Bag 1F'!C16,0)+IF($D$10="Stone Masonry Cement Mortar 2F",'Stone Masonry Cement Mortar 2F'!C16,0)+IF($D$10="Brick Masonry Cement Mortar 2F",'Brick Masonry Cement Mortar 2F'!C16,0)+IF($D$10="Hollow Concrete Block 2F",'Hollow Concrete Block 2F'!C16,0)+IF($D$10="CSEB 2F",'CSEB 2F'!C16,0)+IF($D$10="Timber Structure 2F",'Timber Structure 2F'!C16,0)+IF($D$10="Bamboo Stone Hybrid 2F",'Bamboo Stone Hybrid 2F'!C16,0) -> 0 | D24: ='Material GHG'!C15 -> 0.04948764 | E24: =C24*D24 -> 0 | F24: =E24/$D$11 -> 0 | I24: CSEB | K24: ='Material GHG'!C15 -> 0.04948764 | L24: =J24*K24 -> 0 | M24: =L24/$K$11 -> 0
B25: Timber | C25: =IF($D$10="Stone Masonry Cement Mortar 1F",'Stone Masonry Cement Mortar 1F'!C17,0)+IF($D$10="Stone Masonry Mud Mortar 1F",'Stone Masonry Mud Mortar 1F'!C17,0)+IF($D$10="Brick Masonry Cement Mortar 1F",'Brick Masonry Cement Mortar 1F'!C17,0)+IF($D$10="Brick Masonry Mud Mortar 1F",'Brick Masonry Mud Mortar 1F'!C17,0)+IF($D$10="CSEB 1F",'CSEB 1F'!C17,0)+IF($D$10="Earth Bag 1F",'Earth Bag 1F'!C17,0)+IF($D$10="Stone Masonry Cement Mortar 2F",'Stone Masonry Cement Mortar 2F'!C17,0)+IF($D$10="Brick Masonry Cement Mortar 2F",'Brick Masonry Cement Mortar 2F'!C17,0)+IF($D$10="Hollow Concrete Block 2F",'Hollow Concrete Block 2F'!C17,0)+IF($D$10="CSEB 2F",'CSEB 2F'!C17,0)+IF($D$10="Timber Structure 2F",'Timber Structure 2F'!C17,0)+IF($D$10="Bamboo Stone Hybrid 2F",'Bamboo Stone Hybrid 2F'!C17,0) -> 1793.3 | D25: ='Material GHG'!C16 -> -1.3 | E25: =C25*D25 -> -2331.29 | F25: =E25/$D$11 -> -56.48189 | I25: Timber | K25: ='Material GHG'!C16 -> -1.3 | L25: =J25*K25 -> 0 | M25: =L25/$K$11 -> 0
B26: Mud | C26: =IF($D$10="Stone Masonry Cement Mortar 1F",'Stone Masonry Cement Mortar 1F'!C18,0)+IF($D$10="Stone Masonry Mud Mortar 1F",'Stone Masonry Mud Mortar 1F'!C18,0)+IF($D$10="Brick Masonry Cement Mortar 1F",'Brick Masonry Cement Mortar 1F'!C18,0)+IF($D$10="Brick Masonry Mud Mortar 1F",'Brick Masonry Mud Mortar 1F'!C18,0)+IF($D$10="CSEB 1F",'CSEB 1F'!C18,0)+IF($D$10="Earth Bag 1F",'Earth Bag 1F'!C18,0)+IF($D$10="Stone Masonry Cement Mortar 2F",'Stone Masonry Cement Mortar 2F'!C18,0)+IF($D$10="Brick Masonry Cement Mortar 2F",'Brick Masonry Cement Mortar 2F'!C18,0)+IF($D$10="Hollow Concrete Block 2F",'Hollow Concrete Block 2F'!C18,0)+IF($D$10="CSEB 2F",'CSEB 2F'!C18,0)+IF($D$10="Timber Structure 2F",'Timber Structure 2F'!C18,0)+IF($D$10="Bamboo Stone Hybrid 2F",'Bamboo Stone Hybrid 2F'!C18,0) -> 0 | D26: ='Material GHG'!C17 -> -0.073 | E26: =C26*D26 -> 0 | F26: =E26/$D$11 -> 0 | I26: Mud | K26: ='Material GHG'!C17 -> -0.073 | L26: =J26*K26 -> 0 | M26: =L26/$K$11 -> 0
B27: Stone | C27: =IF($D$10="Stone Masonry Cement Mortar 1F",'Stone Masonry Cement Mortar 1F'!C19,0)+IF($D$10="Stone Masonry Mud Mortar 1F",'Stone Masonry Mud Mortar 1F'!C19,0)+IF($D$10="Brick Masonry Cement Mortar 1F",'Brick Masonry Cement Mortar 1F'!C19,0)+IF($D$10="Brick Masonry Mud Mortar 1F",'Brick Masonry Mud Mortar 1F'!C19,0)+IF($D$10="CSEB 1F",'CSEB 1F'!C19,0)+IF($D$10="Earth Bag 1F",'Earth Bag 1F'!C19,0)+IF($D$10="Stone Masonry Cement Mortar 2F",'Stone Masonry Cement Mortar 2F'!C19,0)+IF($D$10="Brick Masonry Cement Mortar 2F",'Brick Masonry Cement Mortar 2F'!C19,0)+IF($D$10="Hollow Concrete Block 2F",'Hollow Concrete Block 2F'!C19,0)+IF($D$10="CSEB 2F",'CSEB 2F'!C19,0)+IF($D$10="Timber Structure 2F",'Timber Structure 2F'!C19,0)+IF($D$10="Bamboo Stone Hybrid 2F",'Bamboo Stone Hybrid 2F'!C19,0) -> 0 | D27: ='Material GHG'!C18 -> 0 | E27: =C27*D27 -> 0 | F27: =E27/$D$11 -> 0 | I27: Stone | K27: ='Material GHG'!C18 -> 0 | L27: =J27*K27 -> 0 | M27: =L27/$K$11 -> 0
B28: Bamboo | C28: =IF($D$10="Stone Masonry Cement Mortar 1F",'Stone Masonry Cement Mortar 1F'!C20,0)+IF($D$10="Stone Masonry Mud Mortar 1F",'Stone Masonry Mud Mortar 1F'!C20,0)+IF($D$10="Brick Masonry Cement Mortar 1F",'Brick Masonry Cement Mortar 1F'!C20,0)+IF($D$10="Brick Masonry Mud Mortar 1F",'Brick Masonry Mud Mortar 1F'!C20,0)+IF($D$10="CSEB 1F",'CSEB 1F'!C20,0)+IF($D$10="Earth Bag 1F",'Earth Bag 1F'!C20,0)+IF($D$10="Stone Masonry Cement Mortar 2F",'Stone Masonry Cement Mortar 2F'!C20,0)+IF($D$10="Brick Masonry Cement Mortar 2F",'Brick Masonry Cement Mortar 2F'!C20,0)+IF($D$10="Hollow Concrete Block 2F",'Hollow Concrete Block 2F'!C20,0)+IF($D$10="CSEB 2F",'CSEB 2F'!C20,0)+IF($D$10="Timber Structure 2F",'Timber Structure 2F'!C20,0)+IF($D$10="Bamboo Stone Hybrid 2F",'Bamboo Stone Hybrid 2F'!C20,0) -> 0 | D28: ='Material GHG'!C19 -> 0 | E28: =C28*D28 -> 0 | F28: =E28/$D$11 -> 0 | I28: Bamboo | K28: ='Material GHG'!C19 -> 0 | L28: =J28*K28 -> 0 | M28: =L28/$K$11 -> 0
B29: CGI | C29: =IF($D$10="Stone Masonry Cement Mortar 1F",'Stone Masonry Cement Mortar 1F'!C21,0)+IF($D$10="Stone Masonry Mud Mortar 1F",'Stone Masonry Mud Mortar 1F'!C21,0)+IF($D$10="Brick Masonry Cement Mortar 1F",'Brick Masonry Cement Mortar 1F'!C21,0)+IF($D$10="Brick Masonry Mud Mortar 1F",'Brick Masonry Mud Mortar 1F'!C21,0)+IF($D$10="CSEB 1F",'CSEB 1F'!C21,0)+IF($D$10="Earth Bag 1F",'Earth Bag 1F'!C21,0)+IF($D$10="Stone Masonry Cement Mortar 2F",'Stone Masonry Cement Mortar 2F'!C21,0)+IF($D$10="Brick Masonry Cement Mortar 2F",'Brick Masonry Cement Mortar 2F'!C21,0)+IF($D$10="Hollow Concrete Block 2F",'Hollow Concrete Block 2F'!C21,0)+IF($D$10="CSEB 2F",'CSEB 2F'!C21,0)+IF($D$10="Timber Structure 2F",'Timber Structure 2F'!C21,0)+IF($D$10="Bamboo Stone Hybrid 2F",'Bamboo Stone Hybrid 2F'!C21,0) -> 259.05 | D29: ='Material GHG'!C20 -> 3 | E29: =C29*D29 -> 777.15 | F29: =E29/$D$11 -> 18.828589 | I29: CGI | K29: ='Material GHG'!C20 -> 3 | L29: =J29*K29 -> 0 | M29: =L29/$K$11 -> 0
B30: GI | C30: =IF($D$10="Stone Masonry Cement Mortar 1F",'Stone Masonry Cement Mortar 1F'!C22,0)+IF($D$10="Stone Masonry Mud Mortar 1F",'Stone Masonry Mud Mortar 1F'!C22,0)+IF($D$10="Brick Masonry Cement Mortar 1F",'Brick Masonry Cement Mortar 1F'!C22,0)+IF($D$10="Brick Masonry Mud Mortar 1F",'Brick Masonry Mud Mortar 1F'!C22,0)+IF($D$10="CSEB 1F",'CSEB 1F'!C22,0)+IF($D$10="Earth Bag 1F",'Earth Bag 1F'!C22,0)+IF($D$10="Stone Masonry Cement Mortar 2F",'Stone Masonry Cement Mortar 2F'!C22,0)+IF($D$10="Brick Masonry Cement Mortar 2F",'Brick Masonry Cement Mortar 2F'!C22,0)+IF($D$10="Hollow Concrete Block 2F",'Hollow Concrete Block 2F'!C22,0)+IF($D$10="CSEB 2F",'CSEB 2F'!C22,0)+IF($D$10="Timber Structure 2F",'Timber Structure 2F'!C22,0)+IF($D$10="Bamboo Stone Hybrid 2F",'Bamboo Stone Hybrid 2F'!C22,0) -> 0 | D30: ='Material GHG'!C21 -> 3 | E30: =C30*D30 -> 0 | F30: =E30/$D$11 -> 0 | I30: GI | K30: ='Material GHG'!C21 -> 3 | L30: =J30*K30 -> 0 | M30: =L30/$K$11 -> 0
... B35: Slate | C35: =IF($D$10="Stone Masonry Cement Mortar 1F",'Stone Masonry Cement Mortar 1F'!C27,0)+IF($D$10="Stone Masonry Mud Mortar 1F",'Stone Masonry Mud Mortar 1F'!C27,0)+IF($D$10="Brick Masonry Cement Mortar 1F",'Brick Masonry Cement Mortar 1F'!C27,0)+IF($D$10="Brick Masonry Mud Mortar 1F",'Brick Masonry Mud Mortar 1F'!C27,0)+IF($D$10="CSEB 1F",'CSEB 1F'!C27,0)+IF($D$10="Earth Bag 1F",'Earth Bag 1F'!C27,0)+IF($D$10="Stone Masonry Cement Mortar 2F",'Stone Masonry Cement Mortar 2F'!C27,0)+IF($D$10="Brick Masonry Cement Mortar 2F",'Brick Masonry Cement Mortar 2F'!C27,0)+IF($D$10="Hollow Concrete Block 2F",'Hollow Concrete Block 2F'!C27,0)+IF($D$10="CSEB 2F",'CSEB 2F'!C27,0)+IF($D$10="Timber Structure 2F",'Timber Structure 2F'!C27,0)+IF($D$10="Bamboo Stone Hybrid 2F",'Bamboo Stone Hybrid 2F'!C27,0) -> 0 | D35: ='Material GHG'!C26 -> 0 | E35: =C35*D35 -> 0 | F35: =E35/$D$11 -> 0 | I35: Slate | K35: ='Material GHG'!C26 -> 0 | L35: =J35*K35 -> 0 | M35: =L35/$K$11 -> 0
B36: Total Greenhouse Gas Emissions (Production) | E36: =SUM(E19:E35) -> 28254.073 | F36: =SUM(F19:F35) -> 684.53235 | I36: Total Emissions | L36: =SUM(L19:L35) -> 0 | M36: =SUM(M19:M35) -> 0
B39: 4a) Transportation GHG Emissions | I39: 4b) Transportation GHG Emissions
B40: Material Types | C40: Amount of Transported Material (kg) | D40: Number of Trips | E40: Transport Type | F40: Distance (one round trip) (km/m3) | G40: GHG Emissions (kgCO2e) | I40: Material Types | J40: Amount of Transported Material (kg) | K40: Number of Trips | L40: Transport Type | M40: Distance (one round trip) (km/m3) | N40: GHG Emissions (kgCO2e)
B41: Cement | C41: 600 | D41: =ROUNDUP(C19/C41,0) -> 11 | E41: Truck | F41: 20 | G41: =IF('Building GHG Emissions'!E41="Truck",'Transport GHG '!$C$22*'Building GHG Emissions'!F41*D41,0)+IF('Building GHG Emissions'!E41="Car",'Transport GHG '!$C$23*'Building GHG Emissions'!F41*D41,0)+IF('Building GHG Emissions'!E41="Donkey",'Transport GHG '!$C$24*'Building GHG Emissions'!F41*D41,0)+IF('Building GHG Emissions'!E41="Helicopter",'Transport GHG '!$C$25*'Building GHG Emissions'!F41*D41,0) -> 88.44 | I41: Cement | K41: =ROUNDUP(J19/J41,0) -> #DIV/0! | N41: =IF('Building GHG Emissions'!L41="Truck",'Transport GHG '!$C$22*'Building GHG Emissions'!M41*K41,0)+IF('Building GHG Emissions'!L41="Car",'Transport GHG '!$C$23*'Building GHG Emissions'!M41*K41,0)+IF('Building GHG Emissions'!L41="Donkey",'Transport GHG '!$C$24*'Building GHG Emissions'!M41*K41,0)+IF('Building GHG Emissions'!L41="Helicopter",'Transport GHG '!$C$25*'Building GHG Emissions'!M41*K41,0) -> 0
B42: Aggregates | D42: =ROUNDUP(C20/C42,0) -> #DIV/0! | F42: 1 | G42: =IF('Building GHG Emissions'!E42="Truck",'Transport GHG '!$C$22*'Building GHG Emissions'!F42,0)+IF('Building GHG Emissions'!E42="Car",'Transport GHG '!$C$23*'Building GHG Emissions'!F42,0)+IF('Building GHG Emissions'!E42="Donkey",'Transport GHG '!$C$24*'Building GHG Emissions'!F42,0)+IF('Building GHG Emissions'!E42="Helicopter",'Transport GHG '!$C$25*'Building GHG Emissions'!F42) -> 0 | I42: Aggregates | K42: =ROUNDUP(J20/J42,0) -> #DIV/0! | N42: =IF('Building GHG Emissions'!L42="Truck",'Transport GHG '!$C$22*'Building GHG Emissions'!M42,0)+IF('Building GHG Emissions'!L42="Car",'Transport GHG '!$C$23*'Building GHG Emissions'!M42,0)+IF('Building GHG Emissions'!L42="Donkey",'Transport GHG '!$C$24*'Building GHG Emissions'!M42,0)+IF('Building GHG Emissions'!L42="Helicopter",'Transport GHG '!$C$25*'Building GHG Emissions'!M42) -> 0
B43: Sand | D43: =ROUNDUP(C21/C43,0) -> #DIV/0! | F43: 1 | G43: =IF('Building GHG Emissions'!E43="Truck",'Transport GHG '!$C$22*'Building GHG Emissions'!F43,0)+IF('Building GHG Emissions'!E43="Car",'Transport GHG '!$C$23*'Building GHG Emissions'!F43,0)+IF('Building GHG Emissions'!E43="Donkey",'Transport GHG '!$C$24*'Building GHG Emissions'!F43,0)+IF('Building GHG Emissions'!E43="Helicopter",'Transport GHG '!$C$25*'Building GHG Emissions'!F43) -> 0 | I43: Sand | K43: =ROUNDUP(J21/J43,0) -> #DIV/0! | N43: =IF('Building GHG Emissions'!L43="Truck",'Transport GHG '!$C$22*'Building GHG Emissions'!M43,0)+IF('Building GHG Emissions'!L43="Car",'Transport GHG '!$C$23*'Building GHG Emissions'!M43,0)+IF('Building GHG Emissions'!L43="Donkey",'Transport GHG '!$C$24*'Building GHG Emissions'!M43,0)+IF('Building GHG Emissions'!L43="Helicopter",'Transport GHG '!$C$25*'Building GHG Emissions'!M43) -> 0
B44: Steel | D44: =ROUNDUP(C22/C44,0) -> #DIV/0! | F44: 1 | G44: =IF('Building GHG Emissions'!E44="Truck",'Transport GHG '!$C$22*'Building GHG Emissions'!F44,0)+IF('Building GHG Emissions'!E44="Car",'Transport GHG '!$C$23*'Building GHG Emissions'!F44,0)+IF('Building GHG Emissions'!E44="Donkey",'Transport GHG '!$C$24*'Building GHG Emissions'!F44,0)+IF('Building GHG Emissions'!E44="Helicopter",'Transport GHG '!$C$25*'Building GHG Emissions'!F44) -> 0 | I44: Steel | K44: =ROUNDUP(J22/J44,0) -> #DIV/0! | N44: =IF('Building GHG Emissions'!L44="Truck",'Transport GHG '!$C$22*'Building GHG Emissions'!M44,0)+IF('Building GHG Emissions'!L44="Car",'Transport GHG '!$C$23*'Building GHG Emissions'!M44,0)+IF('Building GHG Emissions'!L44="Donkey",'Transport GHG '!$C$24*'Building GHG Emissions'!M44,0)+IF('Building GHG Emissions'!L44="Helicopter",'Transport GHG '!$C$25*'Building GHG Emissions'!M44) -> 0
B45: Brick | D45: =ROUNDUP(C23/C45,0) -> #DIV/0! | G45: =IF('Building GHG Emissions'!E45="Truck",'Transport GHG '!$C$22*'Building GHG Emissions'!F45,0)+IF('Building GHG Emissions'!E45="Car",'Transport GHG '!$C$23*'Building GHG Emissions'!F45,0)+IF('Building GHG Emissions'!E45="Donkey",'Transport GHG '!$C$24*'Building GHG Emissions'!F45,0)+IF('Building GHG Emissions'!E45="Helicopter",'Transport GHG '!$C$25*'Building GHG Emissions'!F45) -> 0 | I45: Brick | K45: =ROUNDUP(J23/J45,0) -> #DIV/0! | N45: =IF('Building GHG Emissions'!L45="Truck",'Transport GHG '!$C$22*'Building GHG Emissions'!M45,0)+IF('Building GHG Emissions'!L45="Car",'Transport GHG '!$C$23*'Building GHG Emissions'!M45,0)+IF('Building GHG Emissions'!L45="Donkey",'Transport GHG '!$C$24*'Building GHG Emissions'!M45,0)+IF('Building GHG Emissions'!L45="Helicopter",'Transport GHG '!$C$25*'Building GHG Emissions'!M45) -> 0
B46: CSEB | D46: =ROUNDUP(C24/C46,0) -> #DIV/0! | G46: =IF('Building GHG Emissions'!E46="Truck",'Transport GHG '!$C$22*'Building GHG Emissions'!F46,0)+IF('Building GHG Emissions'!E46="Car",'Transport GHG '!$C$23*'Building GHG Emissions'!F46,0)+IF('Building GHG Emissions'!E46="Donkey",'Transport GHG '!$C$24*'Building GHG Emissions'!F46,0)+IF('Building GHG Emissions'!E46="Helicopter",'Transport GHG '!$C$25*'Building GHG Emissions'!F46) -> 0 | I46: CSEB | K46: =ROUNDUP(J24/J46,0) -> #DIV/0! | N46: =IF('Building GHG Emissions'!L46="Truck",'Transport GHG '!$C$22*'Building GHG Emissions'!M46,0)+IF('Building GHG Emissions'!L46="Car",'Transport GHG '!$C$23*'Building GHG Emissions'!M46,0)+IF('Building GHG Emissions'!L46="Donkey",'Transport GHG '!$C$24*'Building GHG Emissions'!M46,0)+IF('Building GHG Emissions'!L46="Helicopter",'Transport GHG '!$C$25*'Building GHG Emissions'!M46) -> 0
B47: Timber | D47: =ROUNDUP(C25/C47,0) -> #DIV/0! | G47: =IF('Building GHG Emissions'!E47="Truck",'Transport GHG '!$C$22*'Building GHG Emissions'!F47,0)+IF('Building GHG Emissions'!E47="Car",'Transport GHG '!$C$23*'Building GHG Emissions'!F47,0)+IF('Building GHG Emissions'!E47="Donkey",'Transport GHG '!$C$24*'Building GHG Emissions'!F47,0)+IF('Building GHG Emissions'!E47="Helicopter",'Transport GHG '!$C$25*'Building GHG Emissions'!F47) -> 0 | I47: Timber | K47: =ROUNDUP(J25/J47,0) -> #DIV/0! | N47: =IF('Building GHG Emissions'!L47="Truck",'Transport GHG '!$C$22*'Building GHG Emissions'!M47,0)+IF('Building GHG Emissions'!L47="Car",'Transport GHG '!$C$23*'Building GHG Emissions'!M47,0)+IF('Building GHG Emissions'!L47="Donkey",'Transport GHG '!$C$24*'Building GHG Emissions'!M47,0)+IF('Building GHG Emissions'!L47="Helicopter",'Transport GHG '!$C$25*'Building GHG Emissions'!M47) -> 0
B48: Mud | D48: =ROUNDUP(C26/C48,0) -> #DIV/0! | G48: =IF('Building GHG Emissions'!E48="Truck",'Transport GHG '!$C$22*'Building GHG Emissions'!F48,0)+IF('Building GHG Emissions'!E48="Car",'Transport GHG '!$C$23*'Building GHG Emissions'!F48,0)+IF('Building GHG Emissions'!E48="Donkey",'Transport GHG '!$C$24*'Building GHG Emissions'!F48,0)+IF('Building GHG Emissions'!E48="Helicopter",'Transport GHG '!$C$25*'Building GHG Emissions'!F48) -> 0 | I48: Mud | K48: =ROUNDUP(J26/J48,0) -> #DIV/0! | N48: =IF('Building GHG Emissions'!L48="Truck",'Transport GHG '!$C$22*'Building GHG Emissions'!M48,0)+IF('Building GHG Emissions'!L48="Car",'Transport GHG '!$C$23*'Building GHG Emissions'!M48,0)+IF('Building GHG Emissions'!L48="Donkey",'Transport GHG '!$C$24*'Building GHG Emissions'!M48,0)+IF('Building GHG Emissions'!L48="Helicopter",'Transport GHG '!$C$25*'Building GHG Emissions'!M48) -> 0
B49: Stone | D49: =ROUNDUP(C27/C49,0) -> #DIV/0! | G49: =IF('Building GHG Emissions'!E49="Truck",'Transport GHG '!$C$22*'Building GHG Emissions'!F49,0)+IF('Building GHG Emissions'!E49="Car",'Transport GHG '!$C$23*'Building GHG Emissions'!F49,0)+IF('Building GHG Emissions'!E49="Donkey",'Transport GHG '!$C$24*'Building GHG Emissions'!F49,0)+IF('Building GHG Emissions'!E49="Helicopter",'Transport GHG '!$C$25*'Building GHG Emissions'!F49) -> 0 | I49: Stone | K49: =ROUNDUP(J27/J49,0) -> #DIV/0! | N49: =IF('Building GHG Emissions'!L49="Truck",'Transport GHG '!$C$22*'Building GHG Emissions'!M49,0)+IF('Building GHG Emissions'!L49="Car",'Transport GHG '!$C$23*'Building GHG Emissions'!M49,0)+IF('Building GHG Emissions'!L49="Donkey",'Transport GHG '!$C$24*'Building GHG Emissions'!M49,0)+IF('Building GHG Emissions'!L49="Helicopter",'Transport GHG '!$C$25*'Building GHG Emissions'!M49) -> 0
B50: Bamboo | D50: =ROUNDUP(C28/C50,0) -> #DIV/0! | G50: =IF('Building GHG Emissions'!E50="Truck",'Transport GHG '!$C$22*'Building GHG Emissions'!F50,0)+IF('Building GHG Emissions'!E50="Car",'Transport GHG '!$C$23*'Building GHG Emissions'!F50,0)+IF('Building GHG Emissions'!E50="Donkey",'Transport GHG '!$C$24*'Building GHG Emissions'!F50,0)+IF('Building GHG Emissions'!E50="Helicopter",'Transport GHG '!$C$25*'Building GHG Emissions'!F50) -> 0 | I50: Bamboo | K50: =ROUNDUP(J28/J50,0) -> #DIV/0! | N50: =IF('Building GHG Emissions'!L50="Truck",'Transport GHG '!$C$22*'Building GHG Emissions'!M50,0)+IF('Building GHG Emissions'!L50="Car",'Transport GHG '!$C$23*'Building GHG Emissions'!M50,0)+IF('Building GHG Emissions'!L50="Donkey",'Transport GHG '!$C$24*'Building GHG Emissions'!M50,0)+IF('Building GHG Emissions'!L50="Helicopter",'Transport GHG '!$C$25*'Building GHG Emissions'!M50) -> 0
B51: CGI | D51: =ROUNDUP(C29/C51,0) -> #DIV/0! | G51: =IF('Building GHG Emissions'!E51="Truck",'Transport GHG '!$C$22*'Building GHG Emissions'!F51,0)+IF('Building GHG Emissions'!E51="Car",'Transport GHG '!$C$23*'Building GHG Emissions'!F51,0)+IF('Building GHG Emissions'!E51="Donkey",'Transport GHG '!$C$24*'Building GHG Emissions'!F51,0)+IF('Building GHG Emissions'!E51="Helicopter",'Transport GHG '!$C$25*'Building GHG Emissions'!F51) -> 0 | I51: CGI | K51: =ROUNDUP(J29/J51,0) -> #DIV/0! | N51: =IF('Building GHG Emissions'!L51="Truck",'Transport GHG '!$C$22*'Building GHG Emissions'!M51,0)+IF('Building GHG Emissions'!L51="Car",'Transport GHG '!$C$23*'Building GHG Emissions'!M51,0)+IF('Building GHG Emissions'!L51="Donkey",'Transport GHG '!$C$24*'Building GHG Emissions'!M51,0)+IF('Building GHG Emissions'!L51="Helicopter",'Transport GHG '!$C$25*'Building GHG Emissions'!M51) -> 0
...

Sheet Material GHG
B2: Material Greenhouse Gas Emission Data (No Input Required)
B4: Colour Coding
B5: Nepal Specific Emission Data
B6: Indian Emission Data
B8: 1. Emissions per Building Material
B9: Material Type | C9: kgCO2e/kg | D9: kgCO2e/m3 | E9: Comparison to Indian Emission Data | F9: Assumptions | G9: Source
B10: Cement | C10: 0.91 | F10: Ordinary Portland cement (OPC) | G10: Indian Construction Material Database of Embodied Energy and Global Warming Potential Methodology Report, November 30, 2017
B11: Aggregates | C11: 0.009 | F11: Crusher machine is used and the fuel, electricity and water consumption used for processing is taken into account. | G11: Indian Construction Material Database of Embodied Energy and Global Warming Potential Methodology Report, November 30, 2017
B12: Sand | C12: 0.009 | F12: Crusher machine is used and the fuel, electricity and water consumption used for processing is taken into account. | G12: Indian Construction Material Database of Embodied Energy and Global Warming Potential Methodology Report, November 30, 2017
B13: Steel | C13: 2.9 | G13: Indian Construction Material Database of Embodied Energy and Global Warming Potential Methodology Report, November 30, 2017
B14: Brick | C14: =IF('Building GHG Emissions'!D14="MCBTK",C33,0)+IF('Building GHG Emissions'!D14="Country Fired Brick",'Material GHG'!C32,0)+IF('Building GHG Emissions'!D14="Clamp Kiln",'Material GHG'!C34,0)+IF('Building GHG Emissions'!D14="FCBTK",'Material GHG'!C35,0)+IF('Building GHG Emissions'!D14="VSBK",'Material GHG'!C36,0) -> 0.33482812 | E14: Refer to the Brick Emission Table Below
B15: CSEB | C15: =D15/C44 -> 0.04948764 | D15: 110.11 | E15: Indian Standard: 0.096 kgCO2e/kg with ordianary portland cement (OPC). This reduces to 0.073 kgCO2e/kg if portland cement slag is used and to 0.01 kgCO2e/kg if pulvurized fuel ash (PFA) is used. These values are based on a mechanized process fueled by 1.26kg/m3 diesel and 10% cement stabilization while the auroville values are based on a manual press with 5% cement stabilization. | F15: Manual press, average 5% cement stabilization, average compressive strenght of 5Pa, curing period of 4 weeks | G15: http://www.earth-auroville.com/earth_in_auroville_introduction_en.php
B16: Timber | C16: -1.3 | F16: Air dried timber | G16: Indian Construction Material Database of Embodied Energy and Global Warming Potential Methodology Report, November 30, 2017
B17: Mud | C17: -0.073 | E17: Indian Standard: -0.029kgCO2e/kg which is based on mechanical extraction and takes into account the electricity from a diesel generator to mix the mortar. Extraction and mixing in Nepal is generally done by manual labour and thus the emissions have been reduced accordingly. | F17: The mud mortar consists of clay mixed with organic material and the materials are all extracted and mixed by manual labour | G17: Indian Construction Material Database of Embodied Energy and Global Warming Potential Methodology Report, November 30, 2017
B18: Stone | C18: 0 | F18: Handcut stone (thus no emissions are generated by the production process)
B19: Bamboo
B20: CGI | C20: 3 | G20: Indian Construction Material Database of Embodied Energy and Global Warming Potential Methodology Report, November 30, 2017
B21: GI | C21: 3 | G21: Indian Construction Material Database of Embodied Energy and Global Warming Potential Methodology Report, November 30, 2017
B22: Polythene Sheet
B23: Mild Steel | C23: 2.9 | G23: Indian Construction Material Database of Embodied Energy and Global Warming Potential Methodology Report, November 30, 2017
B24: Hollow Concrete block | C24: 0.29 | F24: Medium density concrete block with ordinary Portland cement | G24: Indian Construction Material Database of Embodied Energy and Global Warming Potential Methodology Report, November 30, 2017
B25: Earth Bag | C25: =0.05*C10+0.01*2.7 -> 0.0725 | F25: 5% cement stabilization (as per the Indian Construction Material Database emissions for cement), emission for plastic (polypropylene) is 2.7kgCO2e (University of Bath), plastic bag is approximately 1% of total earth bag weight. | G25: Plastic Bag: University of Bath, Inventory of Carbon & Energy Version 1.6a
B26: Slate | C26: 0 | F26: Handcut stone (thus no emissions are generated by the production process)
B27: Rammed Earth | C27: -0.0084 | G27: Indian Construction Material Database of Embodied Energy and Global Warming Potential Methodology Report, November 30, 2017
B28: Clay Roof Tile | C28: 0.69 | G28: Indian Construction Material Database of Embodied Energy and Global Warming Potential Methodology Report, November 30, 2017
B29: Lime Mortar | C29: 0.43 | G29: Indian Construction Material Database of Embodied Energy and Global Warming Potential Methodology Report, November 30, 2017
B31: Brick Types | C31: kgCO2e/kg | D31: kgCO2e/m3 | F31: Assumptions | G31: Source
B32: Country Fired Brick | C32: =D32/C53 -> 0.33482812 | D32: 642.87 | F32: Wooden fired bricks in country kilns | G32: http://www.earth-auroville.com/compressed_stabilised_earth_block_en.php
B33: MCBTK | C33: =0.15+0.0044+0.031 -> 0.1854 | E33: Study on Evaluating Energy Conservation Potential of Brick Production in the SAARC Countries from MinErgy Initiatives indicates a values of 0.299kgCO2e/brick (equivalent to 0.15kgCO2/kg with a brick weight of 2.03kg) but does not take into account the consumed water, generated waste and added minerals. Therefore, the emissions associated with water, waste and minerals were added from the Indian Construction Material Database. | F33: MinErgy: 0.299 kgCO2e per brick, brick weight is 2.03kg | G33: Study on Evaluating Energy Conservation Potential of Brick Production in the SAARC Countries, MinErgy Initiatives, Nepal
B34: Clamp Kiln | C34: =0.23+0.044+0.031 -> 0.305 | E34: The emissions associated with water, waste and minerals were added to the MinErgy data from the Indian Construction Material Database. | F34: MinErgy: 0.47 kgCO2e per brick, brick weight is 2.03kg | G34: Study on Evaluating Energy Conservation Potential of Brick Production in the SAARC Countries, MinErgy Initiatives, Nepal
B35: FCBTK | C35: =0.249/2.03+0.0044+0.031 -> 0.1580601 | E35: The emissions associated with water, waste and minerals were added to the MinErgy data from the Indian Construction Material Database. | F35: MinErgy: 0.249 kgCO2e per brick, brick weight is 2.03kg | G35: Study on Evaluating Energy Conservation Potential of Brick Production in the SAARC Countries, MinErgy Initiatives, Nepal
B36: VSBK | C36: =0.17/2.03+0.0044+0.031 -> 0.11914384 | E36: The emissions associated with water, waste and minerals were added to the MinErgy data from the Indian Construction Material Database. | F36: MinErgy: 0.17 kgCO2e per brick, brick weight is 2.03kg | G36: Study on Evaluating Energy Conservation Potential of Brick Production in the SAARC Countries, MinErgy Initiatives, Nepal
B37: Sundried | D37: =C37*0.294*500 -> 0
B40: 2. Density Assumptions
B41: Density of Cement | C41: 1440 | E41: kg/m3 | F41: Indian Standard Code of Practice for Design Loads for Buildings and Structures IS 875 (Part 1) 1987 (Reaffirmed 2008)
B42: Density of Reinforcing Bar | C42: 7850 | E42: kg/m3 | F42: Indian Standard Code of Practice for Design Loads for Buildings and Structures IS 875 (Part 1) 1987 (Reaffirmed 2008)
B43: Weight Bundle CGI | C43: 55 | E43: kg | F43: https://www.sheltercluster.org/sites/default/files/docs/cgi_specification_150708.pdf
B44: Density CSEB | C44: 2225 | E44: kg/m3 | F44: Nepal Design Catalogue for Reconstruction of Earthquake Resistant Houses Volume 2
B45: Density Mildly Steel | C45: 7830 | E45: kg/m3 | F45: Indian Standard Code of Practice for Design Loads for Buildings and Structures IS 875 (Part 1) 1987 (Reaffirmed 2008)
B46: Density Aggregates/Sand | C46: 1600 | E46: kg/m3 | F46: Indian Standard Code of Practice for Design Loads for Buildings and Structures IS 875 (Part 1) 1987 (Reaffirmed 2008)
...

Sheet Transport GHG 
B1: Transportation Greenhouse Gas Emissions Data (No Input Required)
G2: 700l/hour
B3: 1. Helicopter
B4: Tank Size (Liter) | C4: Max Range (km) | D4: Fuel consumption (Liter/km) | E4: CO2e/liter | F4: CO2e/km | G4: Source
B5: 700 | C5: 607 | D5: =B5/C5 -> 1.1532125 | E5: =8.31/3.78 -> 2.1984127 | F5: =E5*D5 -> 2.535237 | G5: http://airbushelicoptersinc.com/products/H135-specifications.asp https://www.epa.gov/sites/production/files/2015-07/documents/emission-factors_2014.pdf
B7: 2. Truck
B8: Average diesel consumption truck: 0.15L/km
B9: kgCO2e per liter diesel: 2.68
B10: Source: CO2 Comparison CSEB vs Fired Bricks in Nepal, Build Up Nepal
B12: 3. Car
B13: kgCO2e per liter gasoline: 2.33
B14: Source: Carbon Dioxide Emissions by the Transportation Sector and Its Impacts on Health in the Kathmandu Valley
B15: Average gasoline consumption: 13.5 km/L | E15: equivalent to | F15: 0.074L/km
B16: Source: Road Transportation Energy Demand and Environmental Emission: A Case of Kathmandu Valley
B20: 4. Summary
B21: Transport Type | C21: kgCO2e/km
B22: Truck | C22: =2.68*0.15 -> 0.402
B23: Car | C23: =0.074*2.33 -> 0.17242
B24: Donkey | C24: 0
B25: Helicopter | C25: 2.54 | D25: 1.43 | E25: Sikorsky

Sheet Stone Masonry Cement Mortar 1F
B2: Stone Masonry Cement Mortar 1F
B4: Dimensions
B5: Floors | C5: 1
B6: GFA (m2) | C6: =6.35*5 -> 31.75
B7: Veranda (m2) | C7: =1.5*6.25 -> 9.375
B8: Total GFA (m2) | C8: =SUM(C6:C7) -> 41.125
I9: Assumptions
B10: Materials | C10: Weight (kg) | D10: Volume (m3) | E10: Bags (50kg per bag) | F10: Bundle | I10: Density of Cement | J10: 1440 | K10: kg/m3
B11: Cement | C11: =E11*50 -> 7050 | D11: =C11/$J$10 -> 4.8958333 | E11: 141 | I11: Density of Reinforcing Bar | J11: 7850 | K11: kg/m3
B12: Aggregates | C12: =D12*J15 -> 14400 | D12: 9 | I12: Weight Bundle CGI | J12: 55 | K12: kg
B13: Sand | C13: =D13*J15 -> 33600 | D13: 21 | I13: Density CSEB | J13: 2225 | K13: kg/m3
B14: Steel | C14: 460 | D14: =C14/$J$11 -> 0.058598726 | I14: Density Mildly Steel | J14: 7830 | K14: kg/m3
B15: Brick | I15: Density Aggregates/Sand | J15: 1600 | K15: kg/m3
B16: CSEB | I16: Density Bamboo | J16: 673 | K16: kg/m3
B17: Timber | C17: =D17*J19 -> 1753.8 | D17: 2.22 | I17: Density Mud | J17: 1906 | K17: kg/m3
B18: Mud | I18: Stone (generic) | J18: 2691 | K18: kg/m3
B19: Stone | C19: =D19*J18 -> 91494 | D19: 34 | I19: Timber (hard timber average) | J19: 790 | K19: kg/m3
B20: Bamboo | I20: Slates | J20: 2800 | K20: kg/m3
B21: CGI | C21: =55*F21 -> 259.05 | D21: =C21/$J$13 -> 0.11642697 | F21: 4.71 | I21: Brick Size | J21: 240x115x57 | K21: mm
B22: GI | I22: Density Brick (average) | J22: 1920 | K22: kg/m3
B23: Polythene Sheet | I23: HCB | J23: 1600 | K23: kg/m3
B24: MS Black Pipe | I24: HCB Size | J24: 40x15x20 | K24: cm
B25: Hollow Concrete block | I25: HCB Mix Ratio | J25: 1:1.5:3 | K25: (C:S:A)
B26: Earth Bag
B27: Slate

Sheet Stone Masonry Mud Mortar 1F
B2: Stone Masonry Mud Mortar 1F
B4: Dimensions
B5: Floors | C5: 1
B6: GFA (m2) | C6: =7.35*6.45-3*2.1 -> 41.1075
B7: Veranda (m2) | C7: =3*2.1 -> 6.3
B8: Total GFA (m2) | C8: =C6+C7 -> 47.4075
I9: Assumptions
B10: Materials | C10: Weight (kg) | D10: Volume (m3) | E10: Area (m2) | I10: Density of Cement | J10: 1440 | K10: kg/m3
B11: Cement | I11: Density of Reinforcing Bar | J11: 7850 | K11: kg/m3
B12: Aggregates | I12: Weight Bundle CGI | J12: 55 | K12: kg
B13: Sand | I13: Density CSEB | J13: 2225 | K13: kg/m3
B14: Steel | I14: Density Mildly Steel | J14: 7830 | K14: kg/m3
B15: Brick | I15: Density Aggregates/Sand | J15: 1600 | K15: kg/m3
B16: CSEB | I16: Density Bamboo | J16: 673 | K16: kg/m3
B17: Timber | C17: =D17*J19 -> 6051.4 | D17: 7.66 | I17: Density Mud | J17: 1906 | K17: kg/m3
B18: Mud | C18: =D18*J17 -> 78146 | D18: 41 | I18: Stone (generic) | J18: 2691 | K18: kg/m3
B19: Stone | C19: =D19*J18 -> 150696 | D19: 56 | I19: Timber (hard timber average) | J19: 790 | K19: kg/m3
B20: Bamboo | I20: Slates | J20: 2800 | K20: kg/m3
B21: CGI | I21: Brick Size | J21: 240x115x57 | K21: mm
B22: GI | I22: Density Brick (average) | J22: 1920 | K22: kg/m3
B23: Polythene Sheet | I23: HCB | J23: 1600 | K23: kg/m3
B24: MS Black Pipe | I24: HCB Size | J24: 40x15x20 | K24: cm
B25: Hollow Concrete block | I25: HCB Mix Ratio | J25: 1:1.5:3 | K25: (C:S:A)
B26: Earth Bag | I26: Slate Thickness | J26: 8 | K26: mm
B27: Slate | C27: =D27*J18 -> 3466.008 | D27: =E27*0.008 -> 1.288 | E27: 161

Sheet Brick Masonry Cement Mortar 1F
B2: Brick Masonry Cement Mortar 1F
B4: Dimensions
B5: Floors | C5: 1
B6: GFA (m2) | C6: =6.35*5 -> 31.75
B7: Veranda (m2) | C7: =1.5*6.35 -> 9.525
B8: Total GFA (m2) | C8: =C6+C7 -> 41.275
B10: Materials | C10: Weight (kg) | D10: Volume (m3) | E10: Bags (50kg per bag) | F10: Bund | G10: Nos | I10: Assumptions
B11: Cement | C11: =E11*50 -> 6350 | D11: =C11/J11 -> 4.4097222 | E11: 127 | I11: Density of Cement | J11: 1440 | K11: kg/m3
B12: Aggregates | C12: =D12*J16 -> 24000 | D12: 15 | I12: Density of Reinforcing Bar | J12: 7850 | K12: kg/m3
B13: Sand | C13: =D13*J16 -> 14400 | D13: 9 | I13: Weight Bundle CGI | J13: 55 | K13: kg
B14: Steel | C14: 460 | D14: =C14/J11 -> 0.31944444 | I14: Density CSEB | J14: 2225 | K14: kg/m3
B15: Brick | C15: =D15*J23 -> 66751.002 | D15: =0.24*0.115*0.057*G15 -> 34.766147 | G15: 22099 | I15: Density Mildly Steel | J15: 7830 | K15: kg/m3
B16: CSEB | I16: Density Aggregates/Sand | J16: 1600 | K16: kg/m3
B17: Timber | C17: =D17*J20 -> 1793.3 | D17: 2.27 | I17: Density Bamboo | J17: 673 | K17: kg/m3
B18: Mud | I18: Density Mud | J18: 1906 | K18: kg/m3
B19: Stone | I19: Stone (generic) | J19: 2691 | K19: kg/m3
B20: Bamboo | I20: Timber (hard timber average) | J20: 790 | K20: kg/m3
B21: CGI | C21: =F21*55 -> 259.05 | D21: =C21/J14 -> 0.11642697 | F21: 4.71 | I21: Slates | J21: 2800 | K21: kg/m3
B22: GI | I22: Brick Size | J22: 240x115x57 | K22: mm
B23: Polythene Sheet | I23: Density Brick (average) | J23: 1920 | K23: kg/m3
B24: MS Black Pipe | I24: HCB | J24: 1600 | K24: kg/m3
B25: Hollow Concrete block | I25: HCB Size | J25: 40x15x20 | K25: cm
B26: Earth Bag | I26: HCB Mix Ratio | J26: 1:1.5:3 | K26: (C:S:A)
B27: Slate

Sheet Brick Masonry Mud Mortar 1F
B2: Brick Masonry Mud Mortar 1F
B4: Dimensions
B5: Floors | C5: 1
B6: GFA (m2) | C6: =7.05*5.75-3*2.1 -> 34.2375
B7: Veranda (m2) | C7: =3*2.1 -> 6.3
B8: Total GFA (m2) | C8: =C6+C7 -> 40.5375
K9: Assumptions
B10: Materials | C10: Weight (kg) | D10: Volume (m3) | E10: Area (m2) | F10: Bundle | G10: Nos | H10: RM | K10: Density of Cement | L10: 1440 | M10: kg/m3
B11: Cement | K11: Density of Reinforcing Bar | L11: 7850 | M11: kg/m3
B12: Aggregates | K12: Weight Bundle CGI | L12: 55 | M12: kg
B13: Sand | K13: Density CSEB | L13: 2225 | M13: kg/m3
B14: Steel | K14: Density Mildly Steel | L14: 7830 | M14: kg/m3
B15: Brick | C15: =D15*L22 -> 710371.54 | D15: =0.24*0.115*0.57*G15 -> 369.98518 | G15: 23518 | K15: Density Aggregates/Sand | L15: 1600 | M15: kg/m3
B16: CSEB | K16: Density Bamboo | L16: 673 | M16: kg/m3
B17: Timber | C17: =D17*L19 -> 3057.3 | D17: 3.87 | K17: Density Mud | L17: 1906 | M17: kg/m3
B18: Mud | C18: =D18*L17 -> 66710 | D18: 35 | K18: Stone (generic) | L18: 2691 | M18: kg/m3
B19: Stone | K19: Timber (hard timber average) | L19: 790 | M19: kg/m3
B20: Bamboo | K20: Slates | L20: 2800 | M20: kg/m3
B21: CGI | C21: =F21*55 -> 220 | D21: =C21/L11 -> 0.028025478 | F21: 4 | K21: Brick Size | L21: 240x115x57 | M21: mm
B22: GI | C22: =D22*L11 -> 27.475 | D22: =H22*0.4/1000*875/1000 -> 0.0035 | H22: 10 | K22: Density Brick (average) | L22: 1920 | M22: kg/m3
B23: Polythene Sheet | K23: HCB | L23: 1600 | M23: kg/m3
B24: MS Black Pipe | K24: HCB Size | L24: 40x15x20 | M24: cm
B25: Hollow Concrete block | K25: HCB Mix Ratio | L25: 1:1.5:3 | M25: (C:S:A)
B26: Earth Bag | K26: GI Thickness | L26: 0.35 | M26: mm
B27: Slate

Sheet CSEB 1F
B2: CSEB 1F
B4: Dimensions
B5: Floors | C5: 1
B6: GFA (m2) | C6: =5.4*2.8+1.7*1.6 -> 17.84
B7: GFA (m2) Veranda | C7: =1.7*3.7 -> 6.29
B8: Total GFA (m2) | C8: =C6+C7 -> 24.13
J9: Assumptions
B10: Materials | C10: Weight (kg) | D10: Volume (m3) | E10: Bags (50kg per bag) | F10: No. | G10: Bundle | H10: m2 | J10: Density of Cement | K10: 1440 | L10: kg/m3
B11: Cement | C11: =E11*50 -> 1210 | D11: =C11/'CSEB 2F'!K10 -> 0.84027778 | E11: 24.2 | J11: Density of Reinforcing Bar | K11: 7850 | L11: kg/m3
B12: Aggregates | D12: 0 | J12: Weight Bundle CGI | K12: 55 | L12: kg
B13: Sand | C13: =D13*K15 -> 5920 | D13: 3.7 | J13: Density CSEB | K13: 2225 | L13: kg/m3
B14: Steel | C14: 237.3 | D14: =C14/'CSEB 2F'!K11 -> 0.030229299 | J14: Density Mildly Steel | K14: 7830 | L14: kg/m3
B15: Brick | J15: Density Aggregates/Sand | K15: 1600 | L15: kg/m3
B16: CSEB | C16: =D16*K13 -> 43494.3 | D16: =0.3*0.2*0.1*F16 -> 19.548 | F16: 3258 | J16: Density Bamboo | K16: 673 | L16: kg/m3
B17: Timber | D17: 2.6 | J17: Density Mud | K17: 1906 | L17: kg/m3
B18: Mud | J18: Stone (generic) | K18: 2691 | L18: kg/m3
B19: Stone | J19: Timber (hard timber average) | K19: 790 | L19: kg/m3
B20: Bamboo | C20: =D20*K16 -> 1672.4049 | D20: =10*(PI()*(POWER(0.075,2)-POWER(0.065,2)))*F20 -> 2.4849998 | F20: 56.5 | J20: Slates | K20: 2800 | L20: kg/m3
B21: CGI | J21: Brick Size | K21: 240x115x57 | L21: mm
B22: GI | C22: =D22*K11 -> 26.9255 | D22: =H22*0.4/1000*875/1000 -> 0.00343 | H22: 9.8 | J22: Density Brick (average) | K22: 1920 | L22: kg/m3
B23: Polythene Sheet | J23: HCB | K23: 1600 | L23: kg/m3
B24: MS Black Pipe / Angle & Plates | J24: HCB Size | K24: 40x15x20 | L24: cm
B25: Hollow Concrete block | J25: HCB Mix Ratio | K25: 1:1.5:3 | L25: (C:S:A)
B26: Earth Bag | J26: Length Bamboo | K26: 10 | L26: m
B27: Slate | J27: Diameter Bamboo | K27: 75 | L27: mm
J28: Thickness Bamboo | K28: 10 | L28: mm

Sheet Earth Bag 1F
B2: Earth Bag 1F
B4: Dimensions
B5: Floors | C5: 1
B6: GFA (m2) | C6: =3.96*2*3.275 -> 25.938
B7: GFA (m2) Veranda | C7: 0
B8: Total GFA (m2) | C8: =C6+C7 -> 25.938
J9: Assumptions
B10: Materials | C10: Weight (kg) | D10: Volume (m3) | E10: Bags (50kg per bag) | F10: No. | G10: Bundle | H10: m2 | J10: Density of Cement | K10: 1440 | L10: kg/m3
B11: Cement | C11: =E11*50 -> 920 | D11: =C11/K10 -> 0.63888889 | E11: 18.4 | J11: Density of Reinforcing Bar | K11: 7850 | L11: kg/m3
B12: Aggregates | C12: =D12*K15 -> 3200 | D12: 2 | J12: Weight Bundle CGI | K12: 55 | L12: kg
B13: Sand | C13: =K15*D13 -> 1600 | D13: 1 | J13: Density CSEB | K13: 2225 | L13: kg/m3
B14: Steel | C14: 237.3 | D14: =C14/K11 -> 0.030229299 | J14: Density Mildly Steel | K14: 7830 | L14: kg/m3
B15: Brick | J15: Density Aggregates/Sand | K15: 1600 | L15: kg/m3
B16: CSEB | J16: Density Bamboo | K16: 673 | L16: kg/m3
B17: Timber | C17: =K19*D17 -> 2291 | D17: 2.9 | J17: Density Mud | K17: 1906 | L17: kg/m3
B18: Mud | J18: Stone (generic) | K18: 2691 | L18: kg/m3
B19: Stone | C19: =D19*K18 -> 33099.3 | D19: 12.3 | J19: Timber (hard timber average) | K19: 790 | L19: kg/m3
B20: Bamboo | J20: Slates | K20: 2800 | L20: kg/m3
B21: CGI | C21: =55*G21 -> 231 | D21: =C21/K13 -> 0.10382022 | G21: 4.2 | J21: Brick Size | K21: 240x115x57 | L21: mm
B22: GI | C22: =D22*K11 -> 21.98 | D22: =H22*0.4/1000*875/1000 -> 0.0028 | H22: 8 | J22: Density Brick (average) | K22: 1920 | L22: kg/m3
B23: Polythene Sheet | J23: HCB | K23: 1600 | L23: kg/m3
B24: MS Black Pipe / Angle & Plates | J24: HCB Size | K24: 40x15x20 | L24: cm
B25: Hollow Concrete block | J25: HCB Mix Ratio | K25: 1:1.5:3 | L25: (C:S:A)
B26: Earth Bag | C26: =D26*K29 -> 40290 | D26: 25.5 | J26: Length Bamboo | K26: 10 | L26: m
B27: Slate | J27: Diameter Bamboo | K27: 75 | L27: mm
J28: Thickness Bamboo | K28: 10 | L28: mm
J29: Earthbag Density | K29: 1580 | L29: kg/m3

Sheet Stone Masonry Cement Mortar 2F
B2: Stone Masonry Cement Mortar 2F
B4: Dimensions
B5: Floors | C5: 2
B6: GFA (m2) | C6: =7.8*4.5*2 -> 70.2
B7: Veranda (m2) | C7: =1.21*7.8 -> 9.438
B8: Total GFA (m2) | C8: =C6+C7 -> 79.638
I9: Assumptions
B10: Materials | C10: Weight (kg) | D10: Volume (m3) | E10: Bags (50kg per bag) | F10: Bundle | G10: Rm | I10: Density of Cement | J10: 1440 | K10: kg/m3
B11: Cement | C11: =E11*50 -> 15550 | D11: =C11/$J$10 -> 10.798611 | E11: 311 | I11: Density of Reinforcing Bar | J11: 7850 | K11: kg/m3
B12: Aggregates | C12: =D12*J15 -> 41600 | D12: 26 | I12: Weight Bundle CGI | J12: 55 | K12: kg
B13: Sand | C13: =D13*J15 -> 76800 | D13: 48 | I13: Density CSEB | J13: 2225 | K13: kg/m3
B14: Steel | C14: 1792 | D14: =C14/$J$11 -> 0.22828025 | I14: Density Mildly Steel | J14: 7830 | K14: kg/m3
B15: Brick | I15: Density Aggregates/Sand | J15: 1600 | K15: kg/m3
B16: CSEB | I16: Density Bamboo | J16: 673 | K16: kg/m3
B17: Timber | C17: =D17*J19 -> 2322.6 | D17: 2.94 | I17: Density Mud | J17: 1906 | K17: kg/m3
B18: Mud | I18: Stone (generic) | J18: 2691 | K18: kg/m3
B19: Stone | C19: =J18*D19 -> 231426 | D19: 86 | I19: Timber (hard timber average) | J19: 790 | K19: kg/m3
B20: Bamboo | I20: Slates | J20: 2800 | K20: kg/m3
B21: CGI | C21: =55*F21 -> 302.5 | D21: =C21/$J$13 -> 0.13595506 | F21: 5.5 | I21: Brick Size | J21: 240x115x57 | K21: mm
B22: GI | C22: =D22*J11 -> 30.2225 | D22: =G22*0.4/1000*875/1000 -> 0.00385 | G22: 11 | I22: Density Brick (average) | J22: 1920 | K22: kg/m3
B23: Polythene Sheet | I23: HCB | J23: 1600 | K23: kg/m3
B24: MS Black Pipe | I24: HCB Size | J24: 40x15x20 | K24: cm
B25: Hollow Concrete block | I25: HCB Mix Ratio | J25: 1:1.5:3 | K25: (C:S:A)
B26: Earth Bag | I26: Length Bamboo | J26: 10 | K26: m
B27: Slate | I27: Diameter Bamboo | J27: 75 | K27: mm
I28: Thickness Bamboo | J28: 10 | K28: mm

Sheet Brick Masonry Cement Mortar 2F
B2: Brick Masonry Cement Mortar 2F
B4: Dimensions
B5: Floors | C5: 2
B6: GFA (m2) | C6: =6.35*5*2 -> 63.5
B7: Veranda (m2) | C7: =1.5*6.35 -> 9.525
B8: Total GFA (m2) | C8: =C6+C7 -> 73.025
B10: Materials | C10: Weight (kg) | D10: Volume (m3) | E10: Bags (50kg per bag) | F10: Bund | G10: Nos | I10: Assumptions
B11: Cement | C11: =E11*55 -> 6985 | D11: =C11/J11 -> 4.8506944 | E11: 127 | I11: Density of Cement | J11: 1440 | K11: kg/m3
B12: Aggregates | C12: =J16*D12 -> 17456 | D12: 10.91 | I12: Density of Reinforcing Bar | J12: 7850 | K12: kg/m3
B13: Sand | C13: =J16*D13 -> 36912 | D13: 23.07 | I13: Weight Bundle CGI | J13: 55 | K13: kg
B14: Steel | C14: 776.35 | D14: =C14/J12 -> 0.098898089 | I14: Density CSEB | J14: 2225 | K14: kg/m3
B15: Brick | C15: =D15*J23 -> 111566.81 | D15: =G15*0.24*0.115*0.057 -> 58.107715 | G15: 36936 | I15: Density Mildly Steel | J15: 7830 | K15: kg/m3
B16: CSEB | I16: Density Aggregates/Sand | J16: 1600 | K16: kg/m3
B17: Timber | C17: =J20*D17 -> 3499.7 | D17: 4.43 | I17: Density Bamboo | J17: 673 | K17: kg/m3
B18: Mud | I18: Density Mud | J18: 1906 | K18: kg/m3
B19: Stone | I19: Stone (generic) | J19: 2691 | K19: kg/m3
B20: Bamboo | I20: Timber (hard timber average) | J20: 790 | K20: kg/m3
B21: CGI | C21: =F21*55 -> 259.05 | D21: =C21/J14 -> 0.11642697 | F21: 4.71 | I21: Slates | J21: 2800 | K21: kg/m3
B22: GI | I22: Brick Size | J22: 240x115x57 | K22: mm
B23: Polythene Sheet | I23: Density Brick (average) | J23: 1920 | K23: kg/m3
B24: MS Black Pipe | I24: HCB | J24: 1600 | K24: kg/m3
B25: Hollow Concrete block | I25: HCB Size | J25: 40x15x20 | K25: cm
B26: Earth Bag | I26: HCB Mix Ratio | J26: 1:1.5:3 | K26: (C:S:A)
B27: Slate | I27: Length Bamboo | J27: 10 | K27: m
I28: Diameter Bamboo | J28: 75 | K28: mm
I29: Thickness Bamboo | J29: 10 | K29: mm

Sheet Hollow Concrete Block 2F
B2: Hollow Concrete Block 2F
B4: Dimensions
B5: Floors | C5: 2
B6: GFA House (m2) | C6: =6.5*3.8*2 -> 49.4
B7: Veranda (m2) | C7: 0
B8: GFA (m2) | C8: =C6+C7 -> 49.4
J9: Assumptions
B10: Materials | C10: Weight (kg) | D10: Volume (m3) | E10: Bags (50kg per bag) | F10: No. | G10: Bundle | H10: m2 | J10: Density of Cement | K10: 1440 | L10: kg/m3
B11: Cement | C11: =E11*50 -> 13105 | D11: =C11/K10 -> 9.1006944 | E11: 262.1 | J11: Density of Reinforcing Bar | K11: 7850 | L11: kg/m3
B12: Aggregates | C12: =D12*K15 -> 47360 | D12: 29.6 | J12: Weight Bundle CGI | K12: 55 | L12: kg
B13: Sand | C13: =D13*K15 -> 23520 | D13: 14.7 | J13: Density CSEB | K13: 2225 | L13: kg/m3
B14: Steel | C14: 2541.9 | D14: =C14/K11 -> 0.32380892 | J14: Density Mildly Steel | K14: 7830 | L14: kg/m3
B15: Brick | J15: Density Aggregates/Sand | K15: 1600 | L15: kg/m3
B16: CSEB | J16: Density Bamboo | K16: 673 | L16: kg/m3
B17: Timber | D17: 0 | J17: Density Mud | K17: 1906 | L17: kg/m3
B18: Mud | J18: Stone (generic) | K18: 2691 | L18: kg/m3
B19: Stone | J19: Timber (hard timber average) | K19: 790 | L19: kg/m3
B20: Bamboo | J20: Slates | K20: 2800 | L20: kg/m3
B21: CGI | C21: =55*G20 -> 0 | D21: =C21/K13 -> 0 | J21: Brick Size | K21: 240x115x57 | L21: mm
B22: GI | J22: Density Brick (average) | K22: 1920 | L22: kg/m3
B23: Polythene Sheet | C23: =H23*1000*0.00925 -> 182.225 | H23: 19.7 | J23: HCB | K23: 1600 | L23: kg/m3
B24: MS Black Pipe / Angle & Plates | J24: HCB Size | K24: 40x15x20 | L24: cm
B25: Hollow Concrete block | C25: =D25*K23 -> 54624 | D25: =F25*0.4*0.2*0.15 -> 34.14 | F25: 2845 | J25: HCB Mix Ratio | K25: 1:1.5:3 | L25: (C:S:A)
B26: Earth Bag | J26: Length Bamboo | K26: 10 | L26: m
B27: Slate | J27: Diameter Bamboo | K27: 75 | L27: mm
J28: Thickness Bamboo | K28: 10 | L28: mm
J29: Polythene Gauge | K29: 1000

Sheet CSEB 2F
B2: CSEB 2F
B4: Dimensions
B5: Floors | C5: 2
B6: GFA (m2) | C6: =7.73*6.737*2 -> 104.15402
B7: GFA (m2) Veranda | C7: =7.73*2 -> 15.46
B8: Total GFA (m2) | C8: =C6+C7 -> 119.61402
J9: Assumptions
B10: Materials | C10: Weight (kg) | D10: Volume (m3) | E10: Bags (50kg per bag) | F10: No. | G10: Bundle | H10: m2 | J10: Density of Cement | K10: 1440 | L10: kg/m3
B11: Cement | C11: =E11*50 -> 7880 | D11: =C11/K10 -> 5.4722222 | E11: 157.6 | J11: Density of Reinforcing Bar | K11: 7850 | L11: kg/m3
B12: Aggregates | C12: =D12*K15 -> 31680 | D12: 19.8 | J12: Weight Bundle CGI | K12: 55 | L12: kg
B13: Sand | C13: =D13*K15 -> 16000 | D13: 10 | J13: Density CSEB | K13: 2225 | L13: kg/m3
B14: Steel | C14: 1410.1 | D14: =C14/K11 -> 0.17963057 | J14: Density Mildly Steel | K14: 7830 | L14: kg/m3
B15: Brick | J15: Density Aggregates/Sand | K15: 1600 | L15: kg/m3
B16: CSEB | C16: =D16*K13 -> 331005.81 | D16: =0.23*0.11*0.55*F16 -> 148.76666 | F16: 10691.1 | J16: Density Bamboo | K16: 673 | L16: kg/m3
B17: Timber | C17: =D17*K19 -> 1343 | D17: 1.7 | J17: Density Mud | K17: 1906 | L17: kg/m3
B18: Mud | J18: Stone (generic) | K18: 2691 | L18: kg/m3
B19: Stone | J19: Timber (hard timber average) | K19: 790 | L19: kg/m3
B20: Bamboo | J20: Slates | K20: 2800 | L20: kg/m3
B21: CGI | C21: =55*G21 -> 451 | D21: =C21/K13 -> 0.20269663 | G21: 8.2 | J21: Brick Size | K21: 240x115x57 | L21: mm
B22: GI | H22: 9.8 | J22: Density Brick (average) | K22: 1920 | L22: kg/m3
B23: Polythene Sheet | J23: HCB | K23: 1600 | L23: kg/m3
B24: MS Black Pipe / Angle & Plates | C24: 1408 | J24: HCB Size | K24: 40x15x20 | L24: cm
B25: Hollow Concrete block | J25: HCB Mix Ratio | K25: 1:1.5:3 | L25: (C:S:A)
B26: Earth Bag | J26: Length Bamboo | K26: 10 | L26: m
B27: Slate | J27: Diameter Bamboo | K27: 75 | L27: mm
J28: Thickness Bamboo | K28: 10 | L28: mm
J35: Correct?

Sheet Timber Structure 2F
B2: Timber 2F
B4: Dimensions
B5: Floors | C5: 2
B6: GFA (m2) House | C6: =9.1*6.59*2-(1.5*9.1*2) -> 92.638
B7: GFA (m2) Veranda | C7: =1.5*9.1*2 -> 27.3
B8: Total GFA (m2) | C8: =SUM(C6:C7) -> 119.938
J9: Assumptions
B10: Materials | C10: Weight (kg) | D10: Volume (m3) | E10: Bags (50kg per bag) | F10: No. | G10: Bundle | H10: m2 | J10: Density of Cement | K10: 1440 | L10: kg/m3
B11: Cement | C11: =E11*50 -> 6520 | E11: 130.4 | J11: Density of Reinforcing Bar | K11: 7850 | L11: kg/m3
B12: Aggregates | C12: =D12*K15 -> 17440 | D12: 10.9 | J12: Weight Bundle CGI | K12: 55 | L12: kg
B13: Sand | C13: =D13*K15 -> 28640 | D13: 17.9 | J13: Density CSEB | K13: 2225 | L13: kg/m3
B14: Steel | C14: 630 | J14: Density Mildly Steel | K14: 7830 | L14: kg/m3
B15: Brick | C15: =D15*K22 -> 11033.141 | D15: =F15*0.24*0.115*0.057 -> 5.7464276 | F15: 3652.7 | J15: Density Aggregates/Sand | K15: 1600 | L15: kg/m3
B16: CSEB | D16: 0 | J16: Density Bamboo | K16: 673 | L16: kg/m3
B17: Timber | C17: =D17*K19 -> 13035 | D17: 16.5 | J17: Density Mud | K17: 1906 | L17: kg/m3
B18: Mud | J18: Stone (generic) | K18: 2691 | L18: kg/m3
B19: Stone | J19: Timber (hard timber average) | K19: 790 | L19: kg/m3
B20: Bamboo | J20: Slates | K20: 2800 | L20: kg/m3
B21: CGI | C21: =55*G21 -> 368.5 | G21: 6.7 | J21: Brick Size | K21: 240x115x57 | L21: mm
B22: GI | C22: =D22*K11 -> 31.3215 | D22: =H22*0.4/1000*875/1000 -> 0.00399 | H22: 11.4 | J22: Density Brick (average) | K22: 1920 | L22: kg/m3
B23: Polythene Sheet | J23: HCB | K23: 1600 | L23: kg/m3
B24: MS Black Pipe / Angle & Plates | C24: 526.3 | J24: HCB Size | K24: 40x15x20 | L24: cm
B25: Hollow Concrete block | J25: HCB Mix Ratio | K25: 1:1.5:3 | L25: (C:S:A)
B26: Earth Bag | D26: 0 | J26: Length Bamboo | K26: 10 | L26: m
B27: Slate | J27: Diameter Bamboo | K27: 75 | L27: mm
J28: Thickness Bamboo | K28: 10 | L28: mm

Sheet Bamboo Stone Hybrid 2F
B2: Bamboo Stone Hybrid 1F
B4: Dimensions
B5: Floors | C5: 2
B6: GFA (m2) House | C6: =7.7*4.52*2+1.93*3.35*2 -> 82.539
B7: GFA (m2) Veranda | C7: =7.7*2.06+2.06*1.93 -> 19.8378
B8: Total GFA (m2) | C8: =SUM(C6:C7) -> 102.3768
J9: Assumptions
B10: Materials | C10: Weight (kg) | D10: Volume (m3) | E10: Bags (50kg per bag) | F10: No. | G10: Bundle | H10: m2 | J10: Density of Cement | K10: 1440 | L10: kg/m3
B11: Cement | D11: 0 | J11: Density of Reinforcing Bar | K11: 7850 | L11: kg/m3
B12: Aggregates | D12: 0 | J12: Weight Bundle CGI | K12: 55 | L12: kg
B13: Sand | D13: 0 | J13: Density CSEB | K13: 2225 | L13: kg/m3
B14: Steel | D14: 0 | J14: Density Mildly Steel | K14: 7830 | L14: kg/m3
B15: Brick | D15: 0 | J15: Density Aggregates/Sand | K15: 1600 | L15: kg/m3
B16: CSEB | D16: 0 | J16: Density Bamboo | K16: 673 | L16: kg/m3
B17: Timber | C17: =D17*K19 -> 1027 | D17: 1.3 | J17: Density Mud | K17: 1906 | L17: kg/m3
B18: Mud | C18: =D18*K17 -> 40216.6 | D18: 21.1 | J18: Stone (generic) | K18: 2691 | L18: kg/m3
B19: Stone | C19: =D19*K18 -> 88533.9 | D19: 32.9 | J19: Timber (hard timber average) | K19: 790 | L19: kg/m3
B20: Bamboo | C20: =D20*K16 -> 6808.0198 | D20: =10*(PI()*(POWER(0.075,2)-POWER(0.065,2)))*F20 -> 10.115928 | F20: 230 | J20: Slates | K20: 2800 | L20: kg/m3
B21: CGI | C21: =55*G21 -> 308 | D21: =C21/K13 -> 0.13842697 | G21: 5.6 | J21: Brick Size | K21: 240x115x57 | L21: mm
B22: GI | C22: =D22*K11 -> 26.10125 | D22: =H22*0.4/1000*875/1000 -> 0.003325 | H22: 9.5 | J22: Density Brick (average) | K22: 1920 | L22: kg/m3
B23: Polythene Sheet | D23: 0 | J23: HCB | K23: 1600 | L23: kg/m3
B24: MS Black Pipe | D24: 0 | J24: HCB Size | K24: 40x15x20 | L24: cm
B25: Hollow Concrete block | D25: 0 | J25: HCB Mix Ratio | K25: 1:1.5:3 | L25: (C:S:A)
B26: Earth Bag | D26: 0 | J26: Length Bamboo | K26: 10 | L26: m
B27: Slate | J27: Diameter Bamboo | K27: 75 | L27: mm
J28: Thickness Bamboo | K28: 10 | L28: mm

Sheet Building Types
B2: Building Type 1 Floor | D2: Brick Type | F2: Roof
B3: Stone Masonry Cement Mortar 1F | D3: Country Fired Brick | F3: CGI
B4: Stone Masonry Mud Mortar 1F | D4: MCBTK | F4: Slate
B5: Brick Masonry Cement Mortar 1F | D5: Clamp Kiln | F5: Thatched Roof
B6: Brick Masonry Mud Mortar 1F | D6: FCBTK | F6: Clay Tiles
B7: CSEB 1F | D7: VSBK | F7: Wooden Roof
B8: Earth Bag 1F | F8: RCC
D9: Sundried
B10: Building Type 2 Floors
B11: Stone Masonry Cement Mortar 2F
B12: Brick Masonry Cement Mortar 2F
B13: Hollow Concrete Block 2F
B14: CSEB 2F
B15: Timber Structure 2F
B16: Bamboo Stone Hybrid 2F
B19: Building Types Chosen
B20: =IF('Building GHG Emissions'!$D$9="1 Floor",'Building Types'!B3,'Building Types'!B11) -> Stone Masonry Cement Mortar 1F
B21: =IF('Building GHG Emissions'!$D$9="1 Floor",'Building Types'!B4,'Building Types'!B12) -> Stone Masonry Mud Mortar 1F
B22: =IF('Building GHG Emissions'!$D$9="1 Floor",'Building Types'!B5,'Building Types'!B13) -> Brick Masonry Cement Mortar 1F
B23: =IF('Building GHG Emissions'!$D$9="1 Floor",'Building Types'!B6,'Building Types'!B14) -> Brick Masonry Mud Mortar 1F
B24: =IF('Building GHG Emissions'!$D$9="1 Floor",'Building Types'!B7,'Building Types'!B15) -> CSEB 1F
B25: =IF('Building GHG Emissions'!$D$9="1 Floor",'Building Types'!B8,'Building Types'!B16) -> Earth Bag 1F

Sheet CO2 Conversions
B2: Source Information | C2: http://www.ghgprotocol.org/sites/default/files/ghgp/Global-Warming-Potential-Values%20%28Feb%2016%202016%29_1.pdf
B3: Source Date | C3: 42948
B5: Name | C5: Chemical Formula | D5: 100 year GWP | E5: Possible Source of Emission
B6: Carbon Dioxide | C6: CO2 | D6: 1 | E6: Fossil fuel combustion
B7: Methane | C7: CH4 | D7: 28 | E7: Decomposition biodegradable material
